Workbook

Sheet Ledger
A1: DIPSEVA LEDGER • Issue=भाड्याने दिले • Return=परत आले • Payment=पैसे जमा
A2: Date तारीख | B2: Customer ग्राहक | C2: Type प्रकार | D2: Item ID कोड | E2: Item Name वस्तू | F2: Qty नग | G2: Rate भाडे | H2: Bill ₹ बिल | I2: Paid ₹ जमा | J2: Pay Mode पेमेंट | K2: Note नोंद
A3: 46204 | B3: Yogesh Caterers | C3: Issue | D3: CTRNG | E3: =IF($D3="","",IFERROR(XLOOKUP($D3,Items!$A:$A,Items!$B:$B),"ERR")) | F3: 1 | G3: 850 | H3: =IF($C3="Issue",IFERROR($F3*$G3,0),0) | I3: 600 | J3: Cash
A4: 46204 | B4: Samarth Sound | C4: Issue | D4: GD | E4: =IF($D4="","",IFERROR(XLOOKUP($D4,Items!$A:$A,Items!$B:$B),"ERR")) | F4: 10 | G4: 15 | H4: =IF($C4="Issue",IFERROR($F4*$G4,0),0) | I4: 150 | J4: Cash
A5: 46204 | B5: Samarth Sound | C5: Issue | D5: AAH | E5: =IF($D5="","",IFERROR(XLOOKUP($D5,Items!$A:$A,Items!$B:$B),"ERR")) | F5: 1 | G5: 800 | H5: =IF($C5="Issue",IFERROR($F5*$G5,0),0) | I5: 800 | J5: Cash
A6: 46204 | B6: Tulja Bhavani Mandap | C6: Issue | D6: CH | E6: =IF($D6="","",IFERROR(XLOOKUP($D6,Items!$A:$A,Items!$B:$B),"ERR")) | F6: 20 | G6: 4 | H6: =IF($C6="Issue",IFERROR($F6*$G6,0),0)
A7: 46204 | B7: Tulja Bhavani Mandap | C7: Issue | D7: CH | E7: =IF($D7="","",IFERROR(XLOOKUP($D7,Items!$A:$A,Items!$B:$B),"ERR")) | F7: 70 | G7: 4 | H7: =IF($C7="Issue",IFERROR($F7*$G7,0),0)
A8: 46204 | B8: CASH | C8: Issue | D8: TBL | E8: =IF($D8="","",IFERROR(XLOOKUP($D8,Items!$A:$A,Items!$B:$B),"ERR")) | F8: 39 | G8: 20 | H8: =IF($C8="Issue",IFERROR($F8*$G8,0),0) | I8: 1000 | J8: Cash | K8: OLD 1000 FIX->780 Avinash gaikwad
A9: 46204 | B9: CASH | C9: Issue | D9: DSH | E9: =IF($D9="","",IFERROR(XLOOKUP($D9,Items!$A:$A,Items!$B:$B),"ERR")) | F9: 200 | G9: 2 | H9: =IF($C9="Issue",IFERROR($F9*$G9,0),0) | I9: 540 | J9: Cash | K9: OLD 540 FIX->400 Avinash gaikwad
A10: 46206 | B10: CASH | C10: Issue | D10: CTRNG | E10: =IF($D10="","",IFERROR(XLOOKUP($D10,Items!$A:$A,Items!$B:$B),"ERR")) | F10: 1 | G10: 50 | H10: =IF($C10="Issue",IFERROR($F10*$G10,0),0) | K10: Vijay jadhav
A11: 46206 | B11: Sunil Garandwal | C11: Issue | D11: HLC | E11: =IF($D11="","",IFERROR(XLOOKUP($D11,Items!$A:$A,Items!$B:$B),"ERR")) | F11: 1 | G11: 300 | H11: =IF($C11="Issue",IFERROR($F11*$G11,0),0) | I11: 300 | J11: Cash
A12: 46207 | B12: Abhiman Kharat | C12: Issue | D12: CTRNG | E12: =IF($D12="","",IFERROR(XLOOKUP($D12,Items!$A:$A,Items!$B:$B),"ERR")) | F12: 1 | G12: 330 | H12: =IF($C12="Issue",IFERROR($F12*$G12,0),0) | I12: 100 | J12: Cash
A13: 46206 | B13: Ganesh Mandap T | C13: Issue | D13: CTRNG | E13: =IF($D13="","",IFERROR(XLOOKUP($D13,Items!$A:$A,Items!$B:$B),"ERR")) | F13: 1 | G13: 450 | H13: =IF($C13="Issue",IFERROR($F13*$G13,0),0)
A14: 46206 | B14: Ganesh Mandap T | C14: Issue | D14: HLC | E14: =IF($D14="","",IFERROR(XLOOKUP($D14,Items!$A:$A,Items!$B:$B),"ERR")) | F14: 1 | G14: 300 | H14: =IF($C14="Issue",IFERROR($F14*$G14,0),0)
A15: 46206 | B15: Atul Salve | C15: Payment | E15: =IF($D15="","",IFERROR(XLOOKUP($D15,Items!$A:$A,Items!$B:$B),"ERR")) | G15: =IF($D15="","",IFERROR(XLOOKUP($D15,Items!$A:$A,Items!$D:$D),0)) | H15: =IF($C15="Issue",IFERROR($F15*$G15,0),0) | I15: 1000 | K15: Advance
A16: 46207 | B16: Vishva Mandap | C16: Issue | D16: SMI | E16: =IF($D16="","",IFERROR(XLOOKUP($D16,Items!$A:$A,Items!$B:$B),"ERR")) | F16: 1 | G16: 300 | H16: =IF($C16="Issue",IFERROR($F16*$G16,0),0) | I16: 300 | J16: Cash
A17: 46207 | B17: Vishva Mandap | C17: Issue | D17: CHCVR | E17: =IF($D17="","",IFERROR(XLOOKUP($D17,Items!$A:$A,Items!$B:$B),"ERR")) | F17: 10 | G17: 10 | H17: =IF($C17="Issue",IFERROR($F17*$G17,0),0) | I17: 100 | J17: Cash
A18: 46207 | B18: Vishva Mandap | C18: Return | D18: CHCVR | E18: =IF($D18="","",IFERROR(XLOOKUP($D18,Items!$A:$A,Items!$B:$B),"ERR")) | F18: 1 | G18: =IF($D18="","",IFERROR(XLOOKUP($D18,Items!$A:$A,Items!$D:$D),0)) | H18: =IF($C18="Issue",IFERROR($F18*$G18,0),0) | K18: old Return
A19: 46208 | B19: Ayush Mandap | C19: Issue | D19: PLN | E19: =IF($D19="","",IFERROR(XLOOKUP($D19,Items!$A:$A,Items!$B:$B),"ERR")) | F19: 1 | G19: 500 | H19: =IF($C19="Issue",IFERROR($F19*$G19,0),0)
A20: 46208 | B20: Ayush Mandap | C20: Issue | D20: MSF | E20: =IF($D20="","",IFERROR(XLOOKUP($D20,Items!$A:$A,Items!$B:$B),"ERR")) | F20: 1 | G20: 700 | H20: =IF($C20="Issue",IFERROR($F20*$G20,0),0) | I20: 700 | J20: Cash
A21: 46208 | B21: Ayush Mandap | C21: Issue | D21: TBL | E21: =IF($D21="","",IFERROR(XLOOKUP($D21,Items!$A:$A,Items!$B:$B),"ERR")) | F21: 15 | G21: 20 | H21: =IF($C21="Issue",IFERROR($F21*$G21,0),0) | I21: 300 | J21: Cash
A22: 46208 | B22: Ayush Mandap | C22: Return | D22: TBL | E22: =IF($D22="","",IFERROR(XLOOKUP($D22,Items!$A:$A,Items!$B:$B),"ERR")) | F22: 1 | G22: =IF($D22="","",IFERROR(XLOOKUP($D22,Items!$A:$A,Items!$D:$D),0)) | H22: =IF($C22="Issue",IFERROR($F22*$G22,0),0) | K22: old Return
A23: 46208 | B23: Ayush Mandap | C23: Issue | D23: SHF | E23: =IF($D23="","",IFERROR(XLOOKUP($D23,Items!$A:$A,Items!$B:$B),"ERR")) | F23: 5 | G23: 50 | H23: =IF($C23="Issue",IFERROR($F23*$G23,0),0) | I23: 250 | J23: Cash
A24: 46208 | B24: Ayush Mandap | C24: Return | D24: SHF | E24: =IF($D24="","",IFERROR(XLOOKUP($D24,Items!$A:$A,Items!$B:$B),"ERR")) | F24: 1 | G24: =IF($D24="","",IFERROR(XLOOKUP($D24,Items!$A:$A,Items!$D:$D),0)) | H24: =IF($C24="Issue",IFERROR($F24*$G24,0),0) | K24: old Return
A25: 46208 | B25: Ayush Mandap | C25: Issue | D25: PLN | E25: =IF($D25="","",IFERROR(XLOOKUP($D25,Items!$A:$A,Items!$B:$B),"ERR")) | F25: 1 | G25: 500 | H25: =IF($C25="Issue",IFERROR($F25*$G25,0),0) | I25: 500 | J25: Cash
A26: 46208 | B26: Yogesh Caterers | C26: Issue | D26: CTRNG | E26: =IF($D26="","",IFERROR(XLOOKUP($D26,Items!$A:$A,Items!$B:$B),"ERR")) | F26: 1 | G26: 900 | H26: =IF($C26="Issue",IFERROR($F26*$G26,0),0)
A27: 46207 | B27: CASH | C27: Issue | D27: FN | E27: =IF($D27="","",IFERROR(XLOOKUP($D27,Items!$A:$A,Items!$B:$B),"ERR")) | F27: 4 | G27: 150 | H27: =IF($C27="Issue",IFERROR($F27*$G27,0),0) | I27: 600 | J27: Cash | K27: Ajay Hiwrale
A28: 46204 | B28: CASH | C28: Issue | D28: GD SET | E28: =IF($D28="","",IFERROR(XLOOKUP($D28,Items!$A:$A,Items!$B:$B),"ERR")) | F28: 10 | G28: 100 | H28: =IF($C28="Issue",IFERROR($F28*$G28,0),0) | I28: 1000 | J28: Cash
A29: 46204 | B29: CASH | C29: Issue | D29: RTBL | E29: =IF($D29="","",IFERROR(XLOOKUP($D29,Items!$A:$A,Items!$B:$B),"ERR")) | F29: 1 | G29: 200 | H29: =IF($C29="Issue",IFERROR($F29*$G29,0),0) | I29: 200 | J29: Cash
A30: 46204 | B30: CASH | C30: Issue | D30: PRD | E30: =IF($D30="","",IFERROR(XLOOKUP($D30,Items!$A:$A,Items!$B:$B),"ERR")) | F30: 1 | G30: 100 | H30: =IF($C30="Issue",IFERROR($F30*$G30,0),0) | I30: 100 | J30: Cash
A31: 46207 | B31: CASH | C31: Issue | D31: DRM | E31: =IF($D31="","",IFERROR(XLOOKUP($D31,Items!$A:$A,Items!$B:$B),"ERR")) | F31: 1 | G31: 20 | H31: =IF($C31="Issue",IFERROR($F31*$G31,0),0) | I31: 120 | J31: Cash | K31: OLD 120 FIX->20 Pritam patil
A32: 46208 | B32: CASH | C32: Issue | D32: CH | E32: =IF($D32="","",IFERROR(XLOOKUP($D32,Items!$A:$A,Items!$B:$B),"ERR")) | F32: 5 | G32: 10 | H32: =IF($C32="Issue",IFERROR($F32*$G32,0),0) | I32: 50 | J32: Cash
A33: 46208 | B33: CASH | C33: Return | D33: CH | E33: =IF($D33="","",IFERROR(XLOOKUP($D33,Items!$A:$A,Items!$B:$B),"ERR")) | F33: 1 | G33: =IF($D33="","",IFERROR(XLOOKUP($D33,Items!$A:$A,Items!$D:$D),0)) | H33: =IF($C33="Issue",IFERROR($F33*$G33,0),0) | K33: old Return
A34: 46208 | B34: CASH | C34: Issue | D34: DSH | E34: =IF($D34="","",IFERROR(XLOOKUP($D34,Items!$A:$A,Items!$B:$B),"ERR")) | F34: 50 | G34: 4 | H34: =IF($C34="Issue",IFERROR($F34*$G34,0),0) | I34: 250 | J34: Cash | K34: OLD 250 FIX->200 Prem Pandit
A35: 46208 | B35: CASH | C35: Return | D35: DSH | E35: =IF($D35="","",IFERROR(XLOOKUP($D35,Items!$A:$A,Items!$B:$B),"ERR")) | F35: 1 | G35: =IF($D35="","",IFERROR(XLOOKUP($D35,Items!$A:$A,Items!$D:$D),0)) | H35: =IF($C35="Issue",IFERROR($F35*$G35,0),0) | K35: old Return
A36: 46209 | B36: CASH | C36: Issue | D36: MT | E36: =IF($D36="","",IFERROR(XLOOKUP($D36,Items!$A:$A,Items!$B:$B),"ERR")) | F36: 2 | G36: 50 | H36: =IF($C36="Issue",IFERROR($F36*$G36,0),0) | I36: 100 | J36: Cash | K36: Vijay Dabhade
A37: 46209 | B37: CASH | C37: Return | D37: MT | E37: =IF($D37="","",IFERROR(XLOOKUP($D37,Items!$A:$A,Items!$B:$B),"ERR")) | F37: 1 | G37: =IF($D37="","",IFERROR(XLOOKUP($D37,Items!$A:$A,Items!$D:$D),0)) | H37: =IF($C37="Issue",IFERROR($F37*$G37,0),0) | K37: old Return
A38: 46208 | B38: CASH | C38: Issue | D38: ASN | E38: =IF($D38="","",IFERROR(XLOOKUP($D38,Items!$A:$A,Items!$B:$B),"ERR")) | F38: 8 | G38: 20 | H38: =IF($C38="Issue",IFERROR($F38*$G38,0),0) | I38: 160 | J38: Cash
A39: 46208 | B39: CASH | C39: Return | D39: ASN | E39: =IF($D39="","",IFERROR(XLOOKUP($D39,Items!$A:$A,Items!$B:$B),"ERR")) | F39: 1 | G39: =IF($D39="","",IFERROR(XLOOKUP($D39,Items!$A:$A,Items!$D:$D),0)) | H39: =IF($C39="Issue",IFERROR($F39*$G39,0),0) | K39: old Return
A40: 46209 | B40: CASH | C40: Issue | D40: CTRNG | E40: =IF($D40="","",IFERROR(XLOOKUP($D40,Items!$A:$A,Items!$B:$B),"ERR")) | F40: 1 | G40: 100 | H40: =IF($C40="Issue",IFERROR($F40*$G40,0),0) | I40: 100 | J40: Cash
...

Sheet Items
A1: ITEMS • वस्तू यादी • भाडे येथूनच Ledger मध्ये auto येईल
A2: Item ID कोड | B2: Item Name वस्तू (EN) | C2: Item Marathi वस्तू (मराठी) | D2: Rate ₹ भाडे | E2: Opening Stock सुरुवातीचा माल | F2: Min Stock किमान | G2: Note
A3: OP BAL | B3: Opening Balance | C3: ओपनिंग | D3: 0
A4: CTRNG | B4: CTRNG | C4: केटरिंग | D4: 0
A5: JC | B5: Jumbo Cooler | C5: जंबो कुलर | D5: 500
A6: CH | B6: Chair | C6: खुर्ची | D6: 4 | E6: 600 | F6: 100
A7: RTBL | B7: Round Table | C7: गोल टेबल | D7: 125
A8: FN | B8: Fan | C8: पंखा | D8: 100
A9: GD | B9: Gadi | C9: गादी | D9: 15
A10: DRM | B10: Drum | C10: ड्रम | D10: 20
A11: TBL | B11: Table | C11: टेबल | D11: 20
A12: AB | B12: Ahuja Speaker | C12: अहुजा स्पीकर | D12: 500
A13: SMI | B13: Samai | C13: समई | D13: 300
A14: WBS | B14: Wash Basin | C14: वॉश बेसिन | D14: 200
A15: BS | B15: Bedsheet | C15: चादर | D15: 5
A16: PLN | B16: Palna | C16: पाळणा | D16: 500
A17: Sm Culr | B17: Small Cooler | C17: छोटा कुलर | D17: 200
A18: FRL | B18: Freel | C18: फ्रिल | D18: 30
... A40: SHF | B40: Shafing Dish | C40: शेफिंग डिश | D40: 50
A41: CSH | B41: CASH | D41: 0
A42: CHD | B42: Chadar | C42: चादर | D42: 10
A43: MT | B43: Matt | C43: मॅट | D43: 30
A44: HW | B44: Hawan Kund | C44: हवन कुंड | D44: 100
A45: DSH | B45: Dish | C45: डिश | D45: 1
A46: PD | B46: Podium | C46: पोडियम | D46: 300
A47: STFRM | B47: Stage Frame | C47: स्टेज फ्रेम | D47: 100
A48: BFR | B48: Buffer | C48: बफर | D48: 100
A49: GDR | B49: Grinder | C49: ग्राइंडर | D49: 300
A50: BK FRL | B50: Black Freel | C50: काळा फ्रिल | D50: 30
A51: THRMS | B51: Thermos | C51: थर्मास | D51: 50
A52: PIPE | B52: PIPE | C52: पाईप | D52: 10
A53: RECPT | B53: RECPT | D53: 0
A54: GD SET | B54: Gadi Set | C54: गादी सेट | D54: 30
A55: Table CVR | B55: Table Cover | C55: टेबल कव्हर | D55: 0
A56: STRN | B56: Satranji | C56: सतरंजी | D56: 50
A57: DIAS | B57: Podium | C57: पोडियम | D57: 300

Sheet Customers
A1: CUSTOMERS • ग्राहक यादी • नाव एकदाच लिहा
A2: Customer ग्राहक | B2: Contact Person व्यक्ती | C2: Phone फोन | D2: Type मंडप/केटरर्स | E2: Address / Marathi Name पत्ता | F2: Opening Due ₹ जुनी बाकी
A3: Ayush Mandap | B3: Ajay Kulkarni | D3: Mandap | F3: 0
A4: Ganesh Mandap T | B4: Shyam Thakur | D4: Mandap | E4: विष्णु ठाकूर | F4: 0
A5: Yogesh Caterers | B5: Anand Bansode | D5: Caterers | F5: 0
A6: Tulja Bhavani Mandap | B6: Sanju Khoje | D6: Mandap | E6: तुळजा भवानी मंडप | F6: 0
A7: Abhiman Kharat | B7: Abhiman Kharat | D7: Caterers | F7: 0
A8: G S Event | B8: Guddu Shinde | D8: Mandap | E8: गुड्डू शिंदे | F8: 0
A9: Jay Hari Mandap | B9: Krushna Panchal | D9: Mandap | E9: पांचाळ महाराज | F9: 0
A10: Maitri Mandap | B10: Sanket Yeole | D10: Mandap | E10: संकेत येवले | F10: 0
A11: Pruthviraj Mandap | B11: Kishor Bhalerao | D11: Mandap | E11: पृथ्वीराज मंडप | F11: 0
A12: Ankit bajaj | B12: Ankit bajaj | D12: Mandap | F12: 0
A13: Saileela Caterers | B13: Sandeep Sontakke | D13: Caterers | E13: संदीप सोनटक्के | F13: 0
A14: Sant Shiromani Mandap | B14: Babasaheb Dabhade | D14: Mandap | E14: संत शिरोमणी मंडप | F14: 0
A15: Ajay Mandap | B15: Ajay Kharat | D15: Mandap | E15: अजय खरात | F15: 0
A16: Sai Pooja Caterers | B16: Sunil Nayar | D16: Caterers | E16: सुनील नायर | F16: 0
A17: Pathare Mandap | B17: Sachin Pathare | D17: Mandap | E17: पठारे मंडप | F17: 0
A18: Golden Mandap | B18: Altaf Patel | D18: Mandap | E18: गोल्डन मंडप | F18: 0
A19: Hotel Ecotel | B19: Kshirsagar | D19: Mandap | F19: 0
A20: Nilesh Chaudahary | B20: Nilesh Chaudahary | D20: Mandap | F20: 0
A21: Renuka Mandap | B21: Rohidas Igve | D21: Mandap | F21: 0
A22: Gautam Kirtikar | B22: Gautam Kirtikar | D22: Mandap | F22: 0
A23: Pawan Dhakne | B23: Pawan Dhakne | D23: Caterers | F23: 0
A24: Sai Shraddha Caterers | B24: Kishor Shinde | D24: Caterers | E24: किशोर शिंदे | F24: 0
A25: B R Mandap | B25: PArvez Shaikh | D25: Mandap | E25: बि आर मंडप | F25: 0
A26: Abdul Rikshaw | B26: Abdul Rikshaw | D26: Mandap | F26: 0
A27: Matoshree lawns | B27: Sachin Wagh | D27: Mandap | F27: 0
A28: Dipak Nikam | B28: Dipak Nikam | D28: Mandap | F28: 0
A29: Balaji Mandap G | B29: Giriraj Uplenchwar | D29: Mandap | E29: बालाजी मंडप | F29: 0
A30: Kishor Mandap | B30: Kishor Chaudhari | D30: Mandap | F30: 0
A31: Mahadev Umrikar | B31: Mahadev Umrikar | D31: Caterers | F31: 0
A32: Balaji Mandap K | B32: Khandre Mama | D32: Mandap | F32: 0
A33: Dashrath Caterers | B33: Babasaheb Borade | D33: Caterers | F33: 0
A34: Dip Mandap | B34: Bhagwat Pawar | D34: Mandap | F34: 0
A35: Dipak Nawale | B35: Dipak Nawale | D35: Mandap | F35: 0
A36: Ganesh Mandap K | B36: Ganesh Kale | D36: Mandap | F36: 0
A37: Kshirsagar Mandap R | B37: Raju Kshirsagar | D37: Mandap | F37: 0
A38: Kshirsagar Mandap S | B38: Shyam Kshirsagar | D38: Mandap | F38: 0
A39: Mahalakshmi Mandap | B39: Abasaheb Tawar | D39: Mandap | F39: 0
A40: Mauli Mandap | B40: Shravan Vaidya | D40: Mandap | F40: 0
...

Sheet Dashboard
A1: DIPSEVA • डॅशबोर्ड • आजची स्थिती एका नजरेत
A2: सर्व आकडे Ledger मधून auto — येथे टाइप करू नका. फक्त H2 तारीख बदला. | G2: Today / आज: | H2: 46218
A3: Total Billed • एकूण बिल | B3: Total Received • जमा | C3: Pending • येणे बाकी | E3: Today Collection • आजची जमा | F3: Today Billed • आजचे बिल | G3: Due Customers • थकबाकीदार | H3: Issue rows
A4: =SUM(Ledger!$H$3:$H$1002) | B4: =SUM(Ledger!$I$3:$I$1002) | C4: =B4-C4 | E4: =SUMIFS(Ledger!$I$3:$I$1002,Ledger!$A$3:$A$1002,$H$2) | F4: =SUMIFS(Ledger!$H$3:$H$1002,Ledger!$A$3:$A$1002,$H$2) | G4: =SUMPRODUCT((Khata!$E$3:$E$202>0)*(Khata!$A$3:$A$202<>"")) | H4: =COUNTIF(Ledger!$C$3:$C$1002,"Issue")
A6: TOP PENDING CUSTOMERS • जास्त बाकी असलेले ग्राहक
A7: # | B7: Customer / ग्राहक | C7: Billed | D7: Received | E7: Pending | F7: Given | G7: Returned | H7: Outside
A8: =1 | B8: =IFERROR(INDEX(Khata!$A:$A,MATCH(LARGE(Khata!$E$3:$E$202,1),Khata!$E$3:$E$202,0)),"") | C8: =IF($B8="","",SUMIFS(Ledger!$H$3:$H$1002,Ledger!$B$3:$B$1002,$B8)+XLOOKUP($B8,Customers!$A:$A,Customers!$F:$F,0)) | D8: =IF($B8="","",SUMIFS(Ledger!$I$3:$I$1002,Ledger!$B$3:$B$1002,$B8)) | E8: =IF($B8="","",$C8-$D8) | F8: =IF($B8="","",SUMIFS(Ledger!$F$3:$F$1002,Ledger!$B$3:$B$1002,$B8,Ledger!$C$3:$C$1002,"Issue")) | G8: =IF($B8="","",SUMIFS(Ledger!$F$3:$F$1002,Ledger!$B$3:$B$1002,$B8,Ledger!$C$3:$C$1002,"Return")) | H8: =IF($B8="","",$F8-$G8)
A9: =2 | B9: =IFERROR(INDEX(Khata!$A:$A,MATCH(LARGE(Khata!$E$3:$E$202,2),Khata!$E$3:$E$202,0)),"") | C9: =IF($B9="","",SUMIFS(Ledger!$H$3:$H$1002,Ledger!$B$3:$B$1002,$B9)+XLOOKUP($B9,Customers!$A:$A,Customers!$F:$F,0)) | D9: =IF($B9="","",SUMIFS(Ledger!$I$3:$I$1002,Ledger!$B$3:$B$1002,$B9)) | E9: =IF($B9="","",$C9-$D9) | F9: =IF($B9="","",SUMIFS(Ledger!$F$3:$F$1002,Ledger!$B$3:$B$1002,$B9,Ledger!$C$3:$C$1002,"Issue")) | G9: =IF($B9="","",SUMIFS(Ledger!$F$3:$F$1002,Ledger!$B$3:$B$1002,$B9,Ledger!$C$3:$C$1002,"Return")) | H9: =IF($B9="","",$F9-$G9)
A10: =3 | B10: =IFERROR(INDEX(Khata!$A:$A,MATCH(LARGE(Khata!$E$3:$E$202,3),Khata!$E$3:$E$202,0)),"") | C10: =IF($B10="","",SUMIFS(Ledger!$H$3:$H$1002,Ledger!$B$3:$B$1002,$B10)+XLOOKUP($B10,Customers!$A:$A,Customers!$F:$F,0)) | D10: =IF($B10="","",SUMIFS(Ledger!$I$3:$I$1002,Ledger!$B$3:$B$1002,$B10)) | E10: =IF($B10="","",$C10-$D10) | F10: =IF($B10="","",SUMIFS(Ledger!$F$3:$F$1002,Ledger!$B$3:$B$1002,$B10,Ledger!$C$3:$C$1002,"Issue")) | G10: =IF($B10="","",SUMIFS(Ledger!$F$3:$F$1002,Ledger!$B$3:$B$1002,$B10,Ledger!$C$3:$C$1002,"Return")) | H10: =IF($B10="","",$F10-$G10)
A11: =4 | B11: =IFERROR(INDEX(Khata!$A:$A,MATCH(LARGE(Khata!$E$3:$E$202,4),Khata!$E$3:$E$202,0)),"") | C11: =IF($B11="","",SUMIFS(Ledger!$H$3:$H$1002,Ledger!$B$3:$B$1002,$B11)+XLOOKUP($B11,Customers!$A:$A,Customers!$F:$F,0)) | D11: =IF($B11="","",SUMIFS(Ledger!$I$3:$I$1002,Ledger!$B$3:$B$1002,$B11)) | E11: =IF($B11="","",$C11-$D11) | F11: =IF($B11="","",SUMIFS(Ledger!$F$3:$F$1002,Ledger!$B$3:$B$1002,$B11,Ledger!$C$3:$C$1002,"Issue")) | G11: =IF($B11="","",SUMIFS(Ledger!$F$3:$F$1002,Ledger!$B$3:$B$1002,$B11,Ledger!$C$3:$C$1002,"Return")) | H11: =IF($B11="","",$F11-$G11)
A12: =5 | B12: =IFERROR(INDEX(Khata!$A:$A,MATCH(LARGE(Khata!$E$3:$E$202,5),Khata!$E$3:$E$202,0)),"") | C12: =IF($B12="","",SUMIFS(Ledger!$H$3:$H$1002,Ledger!$B$3:$B$1002,$B12)+XLOOKUP($B12,Customers!$A:$A,Customers!$F:$F,0)) | D12: =IF($B12="","",SUMIFS(Ledger!$I$3:$I$1002,Ledger!$B$3:$B$1002,$B12)) | E12: =IF($B12="","",$C12-$D12) | F12: =IF($B12="","",SUMIFS(Ledger!$F$3:$F$1002,Ledger!$B$3:$B$1002,$B12,Ledger!$C$3:$C$1002,"Issue")) | G12: =IF($B12="","",SUMIFS(Ledger!$F$3:$F$1002,Ledger!$B$3:$B$1002,$B12,Ledger!$C$3:$C$1002,"Return")) | H12: =IF($B12="","",$F12-$G12)
A13: =6 | B13: =IFERROR(INDEX(Khata!$A:$A,MATCH(LARGE(Khata!$E$3:$E$202,6),Khata!$E$3:$E$202,0)),"") | C13: =IF($B13="","",SUMIFS(Ledger!$H$3:$H$1002,Ledger!$B$3:$B$1002,$B13)+XLOOKUP($B13,Customers!$A:$A,Customers!$F:$F,0)) | D13: =IF($B13="","",SUMIFS(Ledger!$I$3:$I$1002,Ledger!$B$3:$B$1002,$B13)) | E13: =IF($B13="","",$C13-$D13) | F13: =IF($B13="","",SUMIFS(Ledger!$F$3:$F$1002,Ledger!$B$3:$B$1002,$B13,Ledger!$C$3:$C$1002,"Issue")) | G13: =IF($B13="","",SUMIFS(Ledger!$F$3:$F$1002,Ledger!$B$3:$B$1002,$B13,Ledger!$C$3:$C$1002,"Return")) | H13: =IF($B13="","",$F13-$G13)
A14: =7 | B14: =IFERROR(INDEX(Khata!$A:$A,MATCH(LARGE(Khata!$E$3:$E$202,7),Khata!$E$3:$E$202,0)),"") | C14: =IF($B14="","",SUMIFS(Ledger!$H$3:$H$1002,Ledger!$B$3:$B$1002,$B14)+XLOOKUP($B14,Customers!$A:$A,Customers!$F:$F,0)) | D14: =IF($B14="","",SUMIFS(Ledger!$I$3:$I$1002,Ledger!$B$3:$B$1002,$B14)) | E14: =IF($B14="","",$C14-$D14) | F14: =IF($B14="","",SUMIFS(Ledger!$F$3:$F$1002,Ledger!$B$3:$B$1002,$B14,Ledger!$C$3:$C$1002,"Issue")) | G14: =IF($B14="","",SUMIFS(Ledger!$F$3:$F$1002,Ledger!$B$3:$B$1002,$B14,Ledger!$C$3:$C$1002,"Return")) | H14: =IF($B14="","",$F14-$G14)
A15: =8 | B15: =IFERROR(INDEX(Khata!$A:$A,MATCH(LARGE(Khata!$E$3:$E$202,8),Khata!$E$3:$E$202,0)),"") | C15: =IF($B15="","",SUMIFS(Ledger!$H$3:$H$1002,Ledger!$B$3:$B$1002,$B15)+XLOOKUP($B15,Customers!$A:$A,Customers!$F:$F,0)) | D15: =IF($B15="","",SUMIFS(Ledger!$I$3:$I$1002,Ledger!$B$3:$B$1002,$B15)) | E15: =IF($B15="","",$C15-$D15) | F15: =IF($B15="","",SUMIFS(Ledger!$F$3:$F$1002,Ledger!$B$3:$B$1002,$B15,Ledger!$C$3:$C$1002,"Issue")) | G15: =IF($B15="","",SUMIFS(Ledger!$F$3:$F$1002,Ledger!$B$3:$B$1002,$B15,Ledger!$C$3:$C$1002,"Return")) | H15: =IF($B15="","",$F15-$G15)
A16: =9 | B16: =IFERROR(INDEX(Khata!$A:$A,MATCH(LARGE(Khata!$E$3:$E$202,9),Khata!$E$3:$E$202,0)),"") | C16: =IF($B16="","",SUMIFS(Ledger!$H$3:$H$1002,Ledger!$B$3:$B$1002,$B16)+XLOOKUP($B16,Customers!$A:$A,Customers!$F:$F,0)) | D16: =IF($B16="","",SUMIFS(Ledger!$I$3:$I$1002,Ledger!$B$3:$B$1002,$B16)) | E16: =IF($B16="","",$C16-$D16) | F16: =IF($B16="","",SUMIFS(Ledger!$F$3:$F$1002,Ledger!$B$3:$B$1002,$B16,Ledger!$C$3:$C$1002,"Issue")) | G16: =IF($B16="","",SUMIFS(Ledger!$F$3:$F$1002,Ledger!$B$3:$B$1002,$B16,Ledger!$C$3:$C$1002,"Return")) | H16: =IF($B16="","",$F16-$G16)
A17: =10 | B17: =IFERROR(INDEX(Khata!$A:$A,MATCH(LARGE(Khata!$E$3:$E$202,10),Khata!$E$3:$E$202,0)),"") | C17: =IF($B17="","",SUMIFS(Ledger!$H$3:$H$1002,Ledger!$B$3:$B$1002,$B17)+XLOOKUP($B17,Customers!$A:$A,Customers!$F:$F,0)) | D17: =IF($B17="","",SUMIFS(Ledger!$I$3:$I$1002,Ledger!$B$3:$B$1002,$B17)) | E17: =IF($B17="","",$C17-$D17) | F17: =IF($B17="","",SUMIFS(Ledger!$F$3:$F$1002,Ledger!$B$3:$B$1002,$B17,Ledger!$C$3:$C$1002,"Issue")) | G17: =IF($B17="","",SUMIFS(Ledger!$F$3:$F$1002,Ledger!$B$3:$B$1002,$B17,Ledger!$C$3:$C$1002,"Return")) | H17: =IF($B17="","",$F17-$G17)
A19: LOW STOCK • कमी माल
A20: Item ID | B20: Item | C20: Opening | D20: Given | E20: Returned | F20: In Hand | G20: Min | H20: Status
A21: =IFERROR(INDEX(Stock!$A:$A,1+2),"") | B21: =IF($A21="","",XLOOKUP($A21,Items!$A:$A,Items!$B:$B)) | C21: =IF($A21="","",XLOOKUP($A21,Stock!$A:$A,Stock!$B:$B)) | D21: =IF($A21="","",XLOOKUP($A21,Stock!$A:$A,Stock!$C:$C)) | E21: =IF($A21="","",XLOOKUP($A21,Stock!$A:$A,Stock!$D:$D)) | F21: =IF($A21="","",XLOOKUP($A21,Stock!$A:$A,Stock!$E:$E)) | G21: =IF($A21="","",XLOOKUP($A21,Stock!$A:$A,Stock!$F:$F)) | H21: =IF($A21="","",XLOOKUP($A21,Stock!$A:$A,Stock!$H:$H))
A22: =IFERROR(INDEX(Stock!$A:$A,2+2),"") | B22: =IF($A22="","",XLOOKUP($A22,Items!$A:$A,Items!$B:$B)) | C22: =IF($A22="","",XLOOKUP($A22,Stock!$A:$A,Stock!$B:$B)) | D22: =IF($A22="","",XLOOKUP($A22,Stock!$A:$A,Stock!$C:$C)) | E22: =IF($A22="","",XLOOKUP($A22,Stock!$A:$A,Stock!$D:$D)) | F22: =IF($A22="","",XLOOKUP($A22,Stock!$A:$A,Stock!$E:$E)) | G22: =IF($A22="","",XLOOKUP($A22,Stock!$A:$A,Stock!$F:$F)) | H22: =IF($A22="","",XLOOKUP($A22,Stock!$A:$A,Stock!$H:$H))
A23: =IFERROR(INDEX(Stock!$A:$A,3+2),"") | B23: =IF($A23="","",XLOOKUP($A23,Items!$A:$A,Items!$B:$B)) | C23: =IF($A23="","",XLOOKUP($A23,Stock!$A:$A,Stock!$B:$B)) | D23: =IF($A23="","",XLOOKUP($A23,Stock!$A:$A,Stock!$C:$C)) | E23: =IF($A23="","",XLOOKUP($A23,Stock!$A:$A,Stock!$D:$D)) | F23: =IF($A23="","",XLOOKUP($A23,Stock!$A:$A,Stock!$E:$E)) | G23: =IF($A23="","",XLOOKUP($A23,Stock!$A:$A,Stock!$F:$F)) | H23: =IF($A23="","",XLOOKUP($A23,Stock!$A:$A,Stock!$H:$H))
A24: =IFERROR(INDEX(Stock!$A:$A,4+2),"") | B24: =IF($A24="","",XLOOKUP($A24,Items!$A:$A,Items!$B:$B)) | C24: =IF($A24="","",XLOOKUP($A24,Stock!$A:$A,Stock!$B:$B)) | D24: =IF($A24="","",XLOOKUP($A24,Stock!$A:$A,Stock!$C:$C)) | E24: =IF($A24="","",XLOOKUP($A24,Stock!$A:$A,Stock!$D:$D)) | F24: =IF($A24="","",XLOOKUP($A24,Stock!$A:$A,Stock!$E:$E)) | G24: =IF($A24="","",XLOOKUP($A24,Stock!$A:$A,Stock!$F:$F)) | H24: =IF($A24="","",XLOOKUP($A24,Stock!$A:$A,Stock!$H:$H))
A25: =IFERROR(INDEX(Stock!$A:$A,5+2),"") | B25: =IF($A25="","",XLOOKUP($A25,Items!$A:$A,Items!$B:$B)) | C25: =IF($A25="","",XLOOKUP($A25,Stock!$A:$A,Stock!$B:$B)) | D25: =IF($A25="","",XLOOKUP($A25,Stock!$A:$A,Stock!$C:$C)) | E25: =IF($A25="","",XLOOKUP($A25,Stock!$A:$A,Stock!$D:$D)) | F25: =IF($A25="","",XLOOKUP($A25,Stock!$A:$A,Stock!$E:$E)) | G25: =IF($A25="","",XLOOKUP($A25,Stock!$A:$A,Stock!$F:$F)) | H25: =IF($A25="","",XLOOKUP($A25,Stock!$A:$A,Stock!$H:$H))
A26: =IFERROR(INDEX(Stock!$A:$A,6+2),"") | B26: =IF($A26="","",XLOOKUP($A26,Items!$A:$A,Items!$B:$B)) | C26: =IF($A26="","",XLOOKUP($A26,Stock!$A:$A,Stock!$B:$B)) | D26: =IF($A26="","",XLOOKUP($A26,Stock!$A:$A,Stock!$C:$C)) | E26: =IF($A26="","",XLOOKUP($A26,Stock!$A:$A,Stock!$D:$D)) | F26: =IF($A26="","",XLOOKUP($A26,Stock!$A:$A,Stock!$E:$E)) | G26: =IF($A26="","",XLOOKUP($A26,Stock!$A:$A,Stock!$F:$F)) | H26: =IF($A26="","",XLOOKUP($A26,Stock!$A:$A,Stock!$H:$H))
A27: =IFERROR(INDEX(Stock!$A:$A,7+2),"") | B27: =IF($A27="","",XLOOKUP($A27,Items!$A:$A,Items!$B:$B)) | C27: =IF($A27="","",XLOOKUP($A27,Stock!$A:$A,Stock!$B:$B)) | D27: =IF($A27="","",XLOOKUP($A27,Stock!$A:$A,Stock!$C:$C)) | E27: =IF($A27="","",XLOOKUP($A27,Stock!$A:$A,Stock!$D:$D)) | F27: =IF($A27="","",XLOOKUP($A27,Stock!$A:$A,Stock!$E:$E)) | G27: =IF($A27="","",XLOOKUP($A27,Stock!$A:$A,Stock!$F:$F)) | H27: =IF($A27="","",XLOOKUP($A27,Stock!$A:$A,Stock!$H:$H))
A28: =IFERROR(INDEX(Stock!$A:$A,8+2),"") | B28: =IF($A28="","",XLOOKUP($A28,Items!$A:$A,Items!$B:$B)) | C28: =IF($A28="","",XLOOKUP($A28,Stock!$A:$A,Stock!$B:$B)) | D28: =IF($A28="","",XLOOKUP($A28,Stock!$A:$A,Stock!$C:$C)) | E28: =IF($A28="","",XLOOKUP($A28,Stock!$A:$A,Stock!$D:$D)) | F28: =IF($A28="","",XLOOKUP($A28,Stock!$A:$A,Stock!$E:$E)) | G28: =IF($A28="","",XLOOKUP($A28,Stock!$A:$A,Stock!$F:$F)) | H28: =IF($A28="","",XLOOKUP($A28,Stock!$A:$A,Stock!$H:$H))
A30: LAST 10 DAYS • रोजची जमा
A31: Date | B31: Billed | C31: Received | E31: Customer | F31: Billed | G31: Received
A32: =$H$2-9+0 | B32: =SUMIFS(Ledger!$H$3:$H$1002,Ledger!$A$3:$A$1002,$A32) | C32: =SUMIFS(Ledger!$I$3:$I$1002,Ledger!$A$3:$A$1002,$A32) | E32: =IFERROR(INDEX(Khata!$A:$A,0+3),"") | F32: =IF($E32="","",SUMIFS(Ledger!$H$3:$H$1002,Ledger!$B$3:$B$1002,$E32)) | G32: =IF($E32="","",SUMIFS(Ledger!$I$3:$I$1002,Ledger!$B$3:$B$1002,$E32))
A33: =$H$2-9+1 | B33: =SUMIFS(Ledger!$H$3:$H$1002,Ledger!$A$3:$A$1002,$A33) | C33: =SUMIFS(Ledger!$I$3:$I$1002,Ledger!$A$3:$A$1002,$A33) | E33: =IFERROR(INDEX(Khata!$A:$A,1+3),"") | F33: =IF($E33="","",SUMIFS(Ledger!$H$3:$H$1002,Ledger!$B$3:$B$1002,$E33)) | G33: =IF($E33="","",SUMIFS(Ledger!$I$3:$I$1002,Ledger!$B$3:$B$1002,$E33))
A34: =$H$2-9+2 | B34: =SUMIFS(Ledger!$H$3:$H$1002,Ledger!$A$3:$A$1002,$A34) | C34: =SUMIFS(Ledger!$I$3:$I$1002,Ledger!$A$3:$A$1002,$A34) | E34: =IFERROR(INDEX(Khata!$A:$A,2+3),"") | F34: =IF($E34="","",SUMIFS(Ledger!$H$3:$H$1002,Ledger!$B$3:$B$1002,$E34)) | G34: =IF($E34="","",SUMIFS(Ledger!$I$3:$I$1002,Ledger!$B$3:$B$1002,$E34))
A35: =$H$2-9+3 | B35: =SUMIFS(Ledger!$H$3:$H$1002,Ledger!$A$3:$A$1002,$A35) | C35: =SUMIFS(Ledger!$I$3:$I$1002,Ledger!$A$3:$A$1002,$A35) | E35: =IFERROR(INDEX(Khata!$A:$A,3+3),"") | F35: =IF($E35="","",SUMIFS(Ledger!$H$3:$H$1002,Ledger!$B$3:$B$1002,$E35)) | G35: =IF($E35="","",SUMIFS(Ledger!$I$3:$I$1002,Ledger!$B$3:$B$1002,$E35))
A36: =$H$2-9+4 | B36: =SUMIFS(Ledger!$H$3:$H$1002,Ledger!$A$3:$A$1002,$A36) | C36: =SUMIFS(Ledger!$I$3:$I$1002,Ledger!$A$3:$A$1002,$A36) | E36: =IFERROR(INDEX(Khata!$A:$A,4+3),"") | F36: =IF($E36="","",SUMIFS(Ledger!$H$3:$H$1002,Ledger!$B$3:$B$1002,$E36)) | G36: =IF($E36="","",SUMIFS(Ledger!$I$3:$I$1002,Ledger!$B$3:$B$1002,$E36))
A37: =$H$2-9+5 | B37: =SUMIFS(Ledger!$H$3:$H$1002,Ledger!$A$3:$A$1002,$A37) | C37: =SUMIFS(Ledger!$I$3:$I$1002,Ledger!$A$3:$A$1002,$A37) | E37: =IFERROR(INDEX(Khata!$A:$A,5+3),"") | F37: =IF($E37="","",SUMIFS(Ledger!$H$3:$H$1002,Ledger!$B$3:$B$1002,$E37)) | G37: =IF($E37="","",SUMIFS(Ledger!$I$3:$I$1002,Ledger!$B$3:$B$1002,$E37))
A38: =$H$2-9+6 | B38: =SUMIFS(Ledger!$H$3:$H$1002,Ledger!$A$3:$A$1002,$A38) | C38: =SUMIFS(Ledger!$I$3:$I$1002,Ledger!$A$3:$A$1002,$A38) | E38: =IFERROR(INDEX(Khata!$A:$A,6+3),"") | F38: =IF($E38="","",SUMIFS(Ledger!$H$3:$H$1002,Ledger!$B$3:$B$1002,$E38)) | G38: =IF($E38="","",SUMIFS(Ledger!$I$3:$I$1002,Ledger!$B$3:$B$1002,$E38))
A39: =$H$2-9+7 | B39: =SUMIFS(Ledger!$H$3:$H$1002,Ledger!$A$3:$A$1002,$A39) | C39: =SUMIFS(Ledger!$I$3:$I$1002,Ledger!$A$3:$A$1002,$A39) | E39: =IFERROR(INDEX(Khata!$A:$A,7+3),"") | F39: =IF($E39="","",SUMIFS(Ledger!$H$3:$H$1002,Ledger!$B$3:$B$1002,$E39)) | G39: =IF($E39="","",SUMIFS(Ledger!$I$3:$I$1002,Ledger!$B$3:$B$1002,$E39))
A40: =$H$2-9+8 | B40: =SUMIFS(Ledger!$H$3:$H$1002,Ledger!$A$3:$A$1002,$A40) | C40: =SUMIFS(Ledger!$I$3:$I$1002,Ledger!$A$3:$A$1002,$A40) | E40: =IFERROR(INDEX(Khata!$A:$A,8+3),"") | F40: =IF($E40="","",SUMIFS(Ledger!$H$3:$H$1002,Ledger!$B$3:$B$1002,$E40)) | G40: =IF($E40="","",SUMIFS(Ledger!$I$3:$I$1002,Ledger!$B$3:$B$1002,$E40))
A41: =$H$2-9+9 | B41: =SUMIFS(Ledger!$H$3:$H$1002,Ledger!$A$3:$A$1002,$A41) | C41: =SUMIFS(Ledger!$I$3:$I$1002,Ledger!$A$3:$A$1002,$A41) | E41: =IFERROR(INDEX(Khata!$A:$A,9+3),"") | F41: =IF($E41="","",SUMIFS(Ledger!$H$3:$H$1002,Ledger!$B$3:$B$1002,$E41)) | G41: =IF($E41="","",SUMIFS(Ledger!$I$3:$I$1002,Ledger!$B$3:$B$1002,$E41))

Sheet Khata
A1: KHATA • ग्राहक खाते • बेरीज (Yogesh: 850+900 बिल, 600 जमा = 1150 बाकी)
A2: Customer ग्राहक | B2: Billed ₹ एकूण बिल | C2: Received ₹ एकूण जमा | D2: Opening Due जुनी बाकी | E2: Pending ₹ येणे बाकी | F2: Given Qty दिलेले | G2: Outside Qty बाहेर
A3: =IF(Customers!A3="","",Customers!A3) | B3: =IF($A3="","",SUMIFS(Ledger!$H$3:$H$1002,Ledger!$B$3:$B$1002,$A3)) | C3: =IF($A3="","",SUMIFS(Ledger!$I$3:$I$1002,Ledger!$B$3:$B$1002,$A3)) | D3: =IF($A3="","",IFERROR(XLOOKUP($A3,Customers!$A:$A,Customers!$F:$F),0)) | E3: =IF($A3="","",$B3+$D3-$C3) | F3: =IF($A3="","",SUMIFS(Ledger!$F$3:$F$1002,Ledger!$B$3:$B$1002,$A3,Ledger!$C$3:$C$1002,"Issue")) | G3: =IF($A3="","",SUMIFS(Ledger!$F$3:$F$1002,Ledger!$B$3:$B$1002,$A3,Ledger!$C$3:$C$1002,"Issue")-SUMIFS(Ledger!$F$3:$F$1002,Ledger!$B$3:$B$1002,$A3,Ledger!$C$3:$C$1002,"Return"))
A4: =IF(Customers!A4="","",Customers!A4) | B4: =IF($A4="","",SUMIFS(Ledger!$H$3:$H$1002,Ledger!$B$3:$B$1002,$A4)) | C4: =IF($A4="","",SUMIFS(Ledger!$I$3:$I$1002,Ledger!$B$3:$B$1002,$A4)) | D4: =IF($A4="","",IFERROR(XLOOKUP($A4,Customers!$A:$A,Customers!$F:$F),0)) | E4: =IF($A4="","",$B4+$D4-$C4) | F4: =IF($A4="","",SUMIFS(Ledger!$F$3:$F$1002,Ledger!$B$3:$B$1002,$A4,Ledger!$C$3:$C$1002,"Issue")) | G4: =IF($A4="","",SUMIFS(Ledger!$F$3:$F$1002,Ledger!$B$3:$B$1002,$A4,Ledger!$C$3:$C$1002,"Issue")-SUMIFS(Ledger!$F$3:$F$1002,Ledger!$B$3:$B$1002,$A4,Ledger!$C$3:$C$1002,"Return"))
A5: =IF(Customers!A5="","",Customers!A5) | B5: =IF($A5="","",SUMIFS(Ledger!$H$3:$H$1002,Ledger!$B$3:$B$1002,$A5)) | C5: =IF($A5="","",SUMIFS(Ledger!$I$3:$I$1002,Ledger!$B$3:$B$1002,$A5)) | D5: =IF($A5="","",IFERROR(XLOOKUP($A5,Customers!$A:$A,Customers!$F:$F),0)) | E5: =IF($A5="","",$B5+$D5-$C5) | F5: =IF($A5="","",SUMIFS(Ledger!$F$3:$F$1002,Ledger!$B$3:$B$1002,$A5,Ledger!$C$3:$C$1002,"Issue")) | G5: =IF($A5="","",SUMIFS(Ledger!$F$3:$F$1002,Ledger!$B$3:$B$1002,$A5,Ledger!$C$3:$C$1002,"Issue")-SUMIFS(Ledger!$F$3:$F$1002,Ledger!$B$3:$B$1002,$A5,Ledger!$C$3:$C$1002,"Return"))
A6: =IF(Customers!A6="","",Customers!A6) | B6: =IF($A6="","",SUMIFS(Ledger!$H$3:$H$1002,Ledger!$B$3:$B$1002,$A6)) | C6: =IF($A6="","",SUMIFS(Ledger!$I$3:$I$1002,Ledger!$B$3:$B$1002,$A6)) | D6: =IF($A6="","",IFERROR(XLOOKUP($A6,Customers!$A:$A,Customers!$F:$F),0)) | E6: =IF($A6="","",$B6+$D6-$C6) | F6: =IF($A6="","",SUMIFS(Ledger!$F$3:$F$1002,Ledger!$B$3:$B$1002,$A6,Ledger!$C$3:$C$1002,"Issue")) | G6: =IF($A6="","",SUMIFS(Ledger!$F$3:$F$1002,Ledger!$B$3:$B$1002,$A6,Ledger!$C$3:$C$1002,"Issue")-SUMIFS(Ledger!$F$3:$F$1002,Ledger!$B$3:$B$1002,$A6,Ledger!$C$3:$C$1002,"Return"))
A7: =IF(Customers!A7="","",Customers!A7) | B7: =IF($A7="","",SUMIFS(Ledger!$H$3:$H$1002,Ledger!$B$3:$B$1002,$A7)) | C7: =IF($A7="","",SUMIFS(Ledger!$I$3:$I$1002,Ledger!$B$3:$B$1002,$A7)) | D7: =IF($A7="","",IFERROR(XLOOKUP($A7,Customers!$A:$A,Customers!$F:$F),0)) | E7: =IF($A7="","",$B7+$D7-$C7) | F7: =IF($A7="","",SUMIFS(Ledger!$F$3:$F$1002,Ledger!$B$3:$B$1002,$A7,Ledger!$C$3:$C$1002,"Issue")) | G7: =IF($A7="","",SUMIFS(Ledger!$F$3:$F$1002,Ledger!$B$3:$B$1002,$A7,Ledger!$C$3:$C$1002,"Issue")-SUMIFS(Ledger!$F$3:$F$1002,Ledger!$B$3:$B$1002,$A7,Ledger!$C$3:$C$1002,"Return"))
A8: =IF(Customers!A8="","",Customers!A8) | B8: =IF($A8="","",SUMIFS(Ledger!$H$3:$H$1002,Ledger!$B$3:$B$1002,$A8)) | C8: =IF($A8="","",SUMIFS(Ledger!$I$3:$I$1002,Ledger!$B$3:$B$1002,$A8)) | D8: =IF($A8="","",IFERROR(XLOOKUP($A8,Customers!$A:$A,Customers!$F:$F),0)) | E8: =IF($A8="","",$B8+$D8-$C8) | F8: =IF($A8="","",SUMIFS(Ledger!$F$3:$F$1002,Ledger!$B$3:$B$1002,$A8,Ledger!$C$3:$C$1002,"Issue")) | G8: =IF($A8="","",SUMIFS(Ledger!$F$3:$F$1002,Ledger!$B$3:$B$1002,$A8,Ledger!$C$3:$C$1002,"Issue")-SUMIFS(Ledger!$F$3:$F$1002,Ledger!$B$3:$B$1002,$A8,Ledger!$C$3:$C$1002,"Return"))
A9: =IF(Customers!A9="","",Customers!A9) | B9: =IF($A9="","",SUMIFS(Ledger!$H$3:$H$1002,Ledger!$B$3:$B$1002,$A9)) | C9: =IF($A9="","",SUMIFS(Ledger!$I$3:$I$1002,Ledger!$B$3:$B$1002,$A9)) | D9: =IF($A9="","",IFERROR(XLOOKUP($A9,Customers!$A:$A,Customers!$F:$F),0)) | E9: =IF($A9="","",$B9+$D9-$C9) | F9: =IF($A9="","",SUMIFS(Ledger!$F$3:$F$1002,Ledger!$B$3:$B$1002,$A9,Ledger!$C$3:$C$1002,"Issue")) | G9: =IF($A9="","",SUMIFS(Ledger!$F$3:$F$1002,Ledger!$B$3:$B$1002,$A9,Ledger!$C$3:$C$1002,"Issue")-SUMIFS(Ledger!$F$3:$F$1002,Ledger!$B$3:$B$1002,$A9,Ledger!$C$3:$C$1002,"Return"))
A10: =IF(Customers!A10="","",Customers!A10) | B10: =IF($A10="","",SUMIFS(Ledger!$H$3:$H$1002,Ledger!$B$3:$B$1002,$A10)) | C10: =IF($A10="","",SUMIFS(Ledger!$I$3:$I$1002,Ledger!$B$3:$B$1002,$A10)) | D10: =IF($A10="","",IFERROR(XLOOKUP($A10,Customers!$A:$A,Customers!$F:$F),0)) | E10: =IF($A10="","",$B10+$D10-$C10) | F10: =IF($A10="","",SUMIFS(Ledger!$F$3:$F$1002,Ledger!$B$3:$B$1002,$A10,Ledger!$C$3:$C$1002,"Issue")) | G10: =IF($A10="","",SUMIFS(Ledger!$F$3:$F$1002,Ledger!$B$3:$B$1002,$A10,Ledger!$C$3:$C$1002,"Issue")-SUMIFS(Ledger!$F$3:$F$1002,Ledger!$B$3:$B$1002,$A10,Ledger!$C$3:$C$1002,"Return"))
A11: =IF(Customers!A11="","",Customers!A11) | B11: =IF($A11="","",SUMIFS(Ledger!$H$3:$H$1002,Ledger!$B$3:$B$1002,$A11)) | C11: =IF($A11="","",SUMIFS(Ledger!$I$3:$I$1002,Ledger!$B$3:$B$1002,$A11)) | D11: =IF($A11="","",IFERROR(XLOOKUP($A11,Customers!$A:$A,Customers!$F:$F),0)) | E11: =IF($A11="","",$B11+$D11-$C11) | F11: =IF($A11="","",SUMIFS(Ledger!$F$3:$F$1002,Ledger!$B$3:$B$1002,$A11,Ledger!$C$3:$C$1002,"Issue")) | G11: =IF($A11="","",SUMIFS(Ledger!$F$3:$F$1002,Ledger!$B$3:$B$1002,$A11,Ledger!$C$3:$C$1002,"Issue")-SUMIFS(Ledger!$F$3:$F$1002,Ledger!$B$3:$B$1002,$A11,Ledger!$C$3:$C$1002,"Return"))
A12: =IF(Customers!A12="","",Customers!A12) | B12: =IF($A12="","",SUMIFS(Ledger!$H$3:$H$1002,Ledger!$B$3:$B$1002,$A12)) | C12: =IF($A12="","",SUMIFS(Ledger!$I$3:$I$1002,Ledger!$B$3:$B$1002,$A12)) | D12: =IF($A12="","",IFERROR(XLOOKUP($A12,Customers!$A:$A,Customers!$F:$F),0)) | E12: =IF($A12="","",$B12+$D12-$C12) | F12: =IF($A12="","",SUMIFS(Ledger!$F$3:$F$1002,Ledger!$B$3:$B$1002,$A12,Ledger!$C$3:$C$1002,"Issue")) | G12: =IF($A12="","",SUMIFS(Ledger!$F$3:$F$1002,Ledger!$B$3:$B$1002,$A12,Ledger!$C$3:$C$1002,"Issue")-SUMIFS(Ledger!$F$3:$F$1002,Ledger!$B$3:$B$1002,$A12,Ledger!$C$3:$C$1002,"Return"))
A13: =IF(Customers!A13="","",Customers!A13) | B13: =IF($A13="","",SUMIFS(Ledger!$H$3:$H$1002,Ledger!$B$3:$B$1002,$A13)) | C13: =IF($A13="","",SUMIFS(Ledger!$I$3:$I$1002,Ledger!$B$3:$B$1002,$A13)) | D13: =IF($A13="","",IFERROR(XLOOKUP($A13,Customers!$A:$A,Customers!$F:$F),0)) | E13: =IF($A13="","",$B13+$D13-$C13) | F13: =IF($A13="","",SUMIFS(Ledger!$F$3:$F$1002,Ledger!$B$3:$B$1002,$A13,Ledger!$C$3:$C$1002,"Issue")) | G13: =IF($A13="","",SUMIFS(Ledger!$F$3:$F$1002,Ledger!$B$3:$B$1002,$A13,Ledger!$C$3:$C$1002,"Issue")-SUMIFS(Ledger!$F$3:$F$1002,Ledger!$B$3:$B$1002,$A13,Ledger!$C$3:$C$1002,"Return"))
A14: =IF(Customers!A14="","",Customers!A14) | B14: =IF($A14="","",SUMIFS(Ledger!$H$3:$H$1002,Ledger!$B$3:$B$1002,$A14)) | C14: =IF($A14="","",SUMIFS(Ledger!$I$3:$I$1002,Ledger!$B$3:$B$1002,$A14)) | D14: =IF($A14="","",IFERROR(XLOOKUP($A14,Customers!$A:$A,Customers!$F:$F),0)) | E14: =IF($A14="","",$B14+$D14-$C14) | F14: =IF($A14="","",SUMIFS(Ledger!$F$3:$F$1002,Ledger!$B$3:$B$1002,$A14,Ledger!$C$3:$C$1002,"Issue")) | G14: =IF($A14="","",SUMIFS(Ledger!$F$3:$F$1002,Ledger!$B$3:$B$1002,$A14,Ledger!$C$3:$C$1002,"Issue")-SUMIFS(Ledger!$F$3:$F$1002,Ledger!$B$3:$B$1002,$A14,Ledger!$C$3:$C$1002,"Return"))
... A202: =IF(Customers!A202="","",Customers!A202) | B202: =IF($A202="","",SUMIFS(Ledger!$H$3:$H$1002,Ledger!$B$3:$B$1002,$A202)) | C202: =IF($A202="","",SUMIFS(Ledger!$I$3:$I$1002,Ledger!$B$3:$B$1002,$A202)) | D202: =IF($A202="","",IFERROR(XLOOKUP($A202,Customers!$A:$A,Customers!$F:$F),0)) | E202: =IF($A202="","",$B202+$D202-$C202) | F202: =IF($A202="","",SUMIFS(Ledger!$F$3:$F$1002,Ledger!$B$3:$B$1002,$A202,Ledger!$C$3:$C$1002,"Issue")) | G202: =IF($A202="","",SUMIFS(Ledger!$F$3:$F$1002,Ledger!$B$3:$B$1002,$A202,Ledger!$C$3:$C$1002,"Issue")-SUMIFS(Ledger!$F$3:$F$1002,Ledger!$B$3:$B$1002,$A202,Ledger!$C$3:$C$1002,"Return"))

Sheet Stock
A1: STOCK • माल हिशोब • In Hand = Opening + Return - Given
A2: Item ID | B2: Opening | C2: Given दिले | D2: Returned परत | E2: In Hand हातात | F2: Min किमान | G2: Revenue ₹ कमाई | H2: Status
A3: =IF(Items!A3="","",Items!A3) | B3: =IF($A3="","",IFERROR(XLOOKUP($A3,Items!$A:$A,Items!$E:$E),0)) | C3: =IF($A3="","",SUMIFS(Ledger!$F$3:$F$1002,Ledger!$D$3:$D$1002,$A3,Ledger!$C$3:$C$1002,"Issue")) | D3: =IF($A3="","",SUMIFS(Ledger!$F$3:$F$1002,Ledger!$D$3:$D$1002,$A3,Ledger!$C$3:$C$1002,"Return")) | E3: =IF($A3="","",$B3+$D3-$C3) | F3: =IF($A3="","",IFERROR(XLOOKUP($A3,Items!$A:$A,Items!$F:$F),0)) | G3: =IF($A3="","",SUMIFS(Ledger!$H$3:$H$1002,Ledger!$D$3:$D$1002,$A3)) | H3: =IF($A3="","",IF($E3<$F3,"LOW",IF($E3=0,"EMPTY","OK")))
A4: =IF(Items!A4="","",Items!A4) | B4: =IF($A4="","",IFERROR(XLOOKUP($A4,Items!$A:$A,Items!$E:$E),0)) | C4: =IF($A4="","",SUMIFS(Ledger!$F$3:$F$1002,Ledger!$D$3:$D$1002,$A4,Ledger!$C$3:$C$1002,"Issue")) | D4: =IF($A4="","",SUMIFS(Ledger!$F$3:$F$1002,Ledger!$D$3:$D$1002,$A4,Ledger!$C$3:$C$1002,"Return")) | E4: =IF($A4="","",$B4+$D4-$C4) | F4: =IF($A4="","",IFERROR(XLOOKUP($A4,Items!$A:$A,Items!$F:$F),0)) | G4: =IF($A4="","",SUMIFS(Ledger!$H$3:$H$1002,Ledger!$D$3:$D$1002,$A4)) | H4: =IF($A4="","",IF($E4<$F4,"LOW",IF($E4=0,"EMPTY","OK")))
A5: =IF(Items!A5="","",Items!A5) | B5: =IF($A5="","",IFERROR(XLOOKUP($A5,Items!$A:$A,Items!$E:$E),0)) | C5: =IF($A5="","",SUMIFS(Ledger!$F$3:$F$1002,Ledger!$D$3:$D$1002,$A5,Ledger!$C$3:$C$1002,"Issue")) | D5: =IF($A5="","",SUMIFS(Ledger!$F$3:$F$1002,Ledger!$D$3:$D$1002,$A5,Ledger!$C$3:$C$1002,"Return")) | E5: =IF($A5="","",$B5+$D5-$C5) | F5: =IF($A5="","",IFERROR(XLOOKUP($A5,Items!$A:$A,Items!$F:$F),0)) | G5: =IF($A5="","",SUMIFS(Ledger!$H$3:$H$1002,Ledger!$D$3:$D$1002,$A5)) | H5: =IF($A5="","",IF($E5<$F5,"LOW",IF($E5=0,"EMPTY","OK")))
A6: =IF(Items!A6="","",Items!A6) | B6: =IF($A6="","",IFERROR(XLOOKUP($A6,Items!$A:$A,Items!$E:$E),0)) | C6: =IF($A6="","",SUMIFS(Ledger!$F$3:$F$1002,Ledger!$D$3:$D$1002,$A6,Ledger!$C$3:$C$1002,"Issue")) | D6: =IF($A6="","",SUMIFS(Ledger!$F$3:$F$1002,Ledger!$D$3:$D$1002,$A6,Ledger!$C$3:$C$1002,"Return")) | E6: =IF($A6="","",$B6+$D6-$C6) | F6: =IF($A6="","",IFERROR(XLOOKUP($A6,Items!$A:$A,Items!$F:$F),0)) | G6: =IF($A6="","",SUMIFS(Ledger!$H$3:$H$1002,Ledger!$D$3:$D$1002,$A6)) | H6: =IF($A6="","",IF($E6<$F6,"LOW",IF($E6=0,"EMPTY","OK")))
A7: =IF(Items!A7="","",Items!A7) | B7: =IF($A7="","",IFERROR(XLOOKUP($A7,Items!$A:$A,Items!$E:$E),0)) | C7: =IF($A7="","",SUMIFS(Ledger!$F$3:$F$1002,Ledger!$D$3:$D$1002,$A7,Ledger!$C$3:$C$1002,"Issue")) | D7: =IF($A7="","",SUMIFS(Ledger!$F$3:$F$1002,Ledger!$D$3:$D$1002,$A7,Ledger!$C$3:$C$1002,"Return")) | E7: =IF($A7="","",$B7+$D7-$C7) | F7: =IF($A7="","",IFERROR(XLOOKUP($A7,Items!$A:$A,Items!$F:$F),0)) | G7: =IF($A7="","",SUMIFS(Ledger!$H$3:$H$1002,Ledger!$D$3:$D$1002,$A7)) | H7: =IF($A7="","",IF($E7<$F7,"LOW",IF($E7=0,"EMPTY","OK")))
A8: =IF(Items!A8="","",Items!A8) | B8: =IF($A8="","",IFERROR(XLOOKUP($A8,Items!$A:$A,Items!$E:$E),0)) | C8: =IF($A8="","",SUMIFS(Ledger!$F$3:$F$1002,Ledger!$D$3:$D$1002,$A8,Ledger!$C$3:$C$1002,"Issue")) | D8: =IF($A8="","",SUMIFS(Ledger!$F$3:$F$1002,Ledger!$D$3:$D$1002,$A8,Ledger!$C$3:$C$1002,"Return")) | E8: =IF($A8="","",$B8+$D8-$C8) | F8: =IF($A8="","",IFERROR(XLOOKUP($A8,Items!$A:$A,Items!$F:$F),0)) | G8: =IF($A8="","",SUMIFS(Ledger!$H$3:$H$1002,Ledger!$D$3:$D$1002,$A8)) | H8: =IF($A8="","",IF($E8<$F8,"LOW",IF($E8=0,"EMPTY","OK")))
A9: =IF(Items!A9="","",Items!A9) | B9: =IF($A9="","",IFERROR(XLOOKUP($A9,Items!$A:$A,Items!$E:$E),0)) | C9: =IF($A9="","",SUMIFS(Ledger!$F$3:$F$1002,Ledger!$D$3:$D$1002,$A9,Ledger!$C$3:$C$1002,"Issue")) | D9: =IF($A9="","",SUMIFS(Ledger!$F$3:$F$1002,Ledger!$D$3:$D$1002,$A9,Ledger!$C$3:$C$1002,"Return")) | E9: =IF($A9="","",$B9+$D9-$C9) | F9: =IF($A9="","",IFERROR(XLOOKUP($A9,Items!$A:$A,Items!$F:$F),0)) | G9: =IF($A9="","",SUMIFS(Ledger!$H$3:$H$1002,Ledger!$D$3:$D$1002,$A9)) | H9: =IF($A9="","",IF($E9<$F9,"LOW",IF($E9=0,"EMPTY","OK")))
A10: =IF(Items!A10="","",Items!A10) | B10: =IF($A10="","",IFERROR(XLOOKUP($A10,Items!$A:$A,Items!$E:$E),0)) | C10: =IF($A10="","",SUMIFS(Ledger!$F$3:$F$1002,Ledger!$D$3:$D$1002,$A10,Ledger!$C$3:$C$1002,"Issue")) | D10: =IF($A10="","",SUMIFS(Ledger!$F$3:$F$1002,Ledger!$D$3:$D$1002,$A10,Ledger!$C$3:$C$1002,"Return")) | E10: =IF($A10="","",$B10+$D10-$C10) | F10: =IF($A10="","",IFERROR(XLOOKUP($A10,Items!$A:$A,Items!$F:$F),0)) | G10: =IF($A10="","",SUMIFS(Ledger!$H$3:$H$1002,Ledger!$D$3:$D$1002,$A10)) | H10: =IF($A10="","",IF($E10<$F10,"LOW",IF($E10=0,"EMPTY","OK")))
A11: =IF(Items!A11="","",Items!A11) | B11: =IF($A11="","",IFERROR(XLOOKUP($A11,Items!$A:$A,Items!$E:$E),0)) | C11: =IF($A11="","",SUMIFS(Ledger!$F$3:$F$1002,Ledger!$D$3:$D$1002,$A11,Ledger!$C$3:$C$1002,"Issue")) | D11: =IF($A11="","",SUMIFS(Ledger!$F$3:$F$1002,Ledger!$D$3:$D$1002,$A11,Ledger!$C$3:$C$1002,"Return")) | E11: =IF($A11="","",$B11+$D11-$C11) | F11: =IF($A11="","",IFERROR(XLOOKUP($A11,Items!$A:$A,Items!$F:$F),0)) | G11: =IF($A11="","",SUMIFS(Ledger!$H$3:$H$1002,Ledger!$D$3:$D$1002,$A11)) | H11: =IF($A11="","",IF($E11<$F11,"LOW",IF($E11=0,"EMPTY","OK")))
A12: =IF(Items!A12="","",Items!A12) | B12: =IF($A12="","",IFERROR(XLOOKUP($A12,Items!$A:$A,Items!$E:$E),0)) | C12: =IF($A12="","",SUMIFS(Ledger!$F$3:$F$1002,Ledger!$D$3:$D$1002,$A12,Ledger!$C$3:$C$1002,"Issue")) | D12: =IF($A12="","",SUMIFS(Ledger!$F$3:$F$1002,Ledger!$D$3:$D$1002,$A12,Ledger!$C$3:$C$1002,"Return")) | E12: =IF($A12="","",$B12+$D12-$C12) | F12: =IF($A12="","",IFERROR(XLOOKUP($A12,Items!$A:$A,Items!$F:$F),0)) | G12: =IF($A12="","",SUMIFS(Ledger!$H$3:$H$1002,Ledger!$D$3:$D$1002,$A12)) | H12: =IF($A12="","",IF($E12<$F12,"LOW",IF($E12=0,"EMPTY","OK")))
A13: =IF(Items!A13="","",Items!A13) | B13: =IF($A13="","",IFERROR(XLOOKUP($A13,Items!$A:$A,Items!$E:$E),0)) | C13: =IF($A13="","",SUMIFS(Ledger!$F$3:$F$1002,Ledger!$D$3:$D$1002,$A13,Ledger!$C$3:$C$1002,"Issue")) | D13: =IF($A13="","",SUMIFS(Ledger!$F$3:$F$1002,Ledger!$D$3:$D$1002,$A13,Ledger!$C$3:$C$1002,"Return")) | E13: =IF($A13="","",$B13+$D13-$C13) | F13: =IF($A13="","",IFERROR(XLOOKUP($A13,Items!$A:$A,Items!$F:$F),0)) | G13: =IF($A13="","",SUMIFS(Ledger!$H$3:$H$1002,Ledger!$D$3:$D$1002,$A13)) | H13: =IF($A13="","",IF($E13<$F13,"LOW",IF($E13=0,"EMPTY","OK")))
A14: =IF(Items!A14="","",Items!A14) | B14: =IF($A14="","",IFERROR(XLOOKUP($A14,Items!$A:$A,Items!$E:$E),0)) | C14: =IF($A14="","",SUMIFS(Ledger!$F$3:$F$1002,Ledger!$D$3:$D$1002,$A14,Ledger!$C$3:$C$1002,"Issue")) | D14: =IF($A14="","",SUMIFS(Ledger!$F$3:$F$1002,Ledger!$D$3:$D$1002,$A14,Ledger!$C$3:$C$1002,"Return")) | E14: =IF($A14="","",$B14+$D14-$C14) | F14: =IF($A14="","",IFERROR(XLOOKUP($A14,Items!$A:$A,Items!$F:$F),0)) | G14: =IF($A14="","",SUMIFS(Ledger!$H$3:$H$1002,Ledger!$D$3:$D$1002,$A14)) | H14: =IF($A14="","",IF($E14<$F14,"LOW",IF($E14=0,"EMPTY","OK")))
... A202: =IF(Items!A202="","",Items!A202) | B202: =IF($A202="","",IFERROR(XLOOKUP($A202,Items!$A:$A,Items!$E:$E),0)) | C202: =IF($A202="","",SUMIFS(Ledger!$F$3:$F$1002,Ledger!$D$3:$D$1002,$A202,Ledger!$C$3:$C$1002,"Issue")) | D202: =IF($A202="","",SUMIFS(Ledger!$F$3:$F$1002,Ledger!$D$3:$D$1002,$A202,Ledger!$C$3:$C$1002,"Return")) | E202: =IF($A202="","",$B202+$D202-$C202) | F202: =IF($A202="","",IFERROR(XLOOKUP($A202,Items!$A:$A,Items!$F:$F),0)) | G202: =IF($A202="","",SUMIFS(Ledger!$H$3:$H$1002,Ledger!$D$3:$D$1002,$A202)) | H202: =IF($A202="","",IF($E202<$F202,"LOW",IF($E202=0,"EMPTY","OK")))

Sheet Statement
A1: STATEMENT • ग्राहक बिल • वर ग्राहक निवडा
A2: Select Customer: | B2: Yogesh Caterers | F2: =SUMIFS(Ledger!$H:$H,Ledger!$B:$B,$B$2)+IFERROR(XLOOKUP($B$2,Customers!$A:$A,Customers!$F:$F),0) | G2: =SUMIFS(Ledger!$I:$I,Ledger!$B:$B,$B$2) | H2: =$F$2-$G$2
F3: Total Bill | G3: Received | H3: Pending
A4: WhatsApp: | B4: ="Namaskar "&$B$2&", DipSeva hisob: Bill Rs"&TEXT($F$2,"#,##0")&", Jama Rs"&TEXT($G$2,"#,##0")&", Baki Rs"&TEXT($H$2,"#,##0")&" - Dhanyavad"
A5: Date | B5: Type | C5: Item ID | D5: Item | E5: Qty | F5: Bill | G5: Paid | H5: Note
A6: =IFERROR(INDEX(Ledger!$A:$A,AGGREGATE(15,6,ROW(Ledger!$B$3:$B$1002)/(Ledger!$B$3:$B$1002=$B$2),1)),"") | B6: =IF($A6="","",INDEX(Ledger!$C:$C,AGGREGATE(15,6,ROW(Ledger!$B$3:$B$1002)/(Ledger!$B$3:$B$1002=$B$2),1))) | C6: =IF($A6="","",INDEX(Ledger!$D:$D,AGGREGATE(15,6,ROW(Ledger!$B$3:$B$1002)/(Ledger!$B$3:$B$1002=$B$2),1))) | D6: =IF($A6="","",INDEX(Ledger!$E:$E,AGGREGATE(15,6,ROW(Ledger!$B$3:$B$1002)/(Ledger!$B$3:$B$1002=$B$2),1))) | E6: =IF($A6="","",INDEX(Ledger!$F:$F,AGGREGATE(15,6,ROW(Ledger!$B$3:$B$1002)/(Ledger!$B$3:$B$1002=$B$2),1))) | F6: =IF($A6="","",INDEX(Ledger!$H:$H,AGGREGATE(15,6,ROW(Ledger!$B$3:$B$1002)/(Ledger!$B$3:$B$1002=$B$2),1))) | G6: =IF($A6="","",INDEX(Ledger!$I:$I,AGGREGATE(15,6,ROW(Ledger!$B$3:$B$1002)/(Ledger!$B$3:$B$1002=$B$2),1))) | H6: =IF($A6="","",INDEX(Ledger!$K:$K,AGGREGATE(15,6,ROW(Ledger!$B$3:$B$1002)/(Ledger!$B$3:$B$1002=$B$2),1)))
A7: =IFERROR(INDEX(Ledger!$A:$A,AGGREGATE(15,6,ROW(Ledger!$B$3:$B$1002)/(Ledger!$B$3:$B$1002=$B$2),2)),"") | B7: =IF($A7="","",INDEX(Ledger!$C:$C,AGGREGATE(15,6,ROW(Ledger!$B$3:$B$1002)/(Ledger!$B$3:$B$1002=$B$2),2))) | C7: =IF($A7="","",INDEX(Ledger!$D:$D,AGGREGATE(15,6,ROW(Ledger!$B$3:$B$1002)/(Ledger!$B$3:$B$1002=$B$2),2))) | D7: =IF($A7="","",INDEX(Ledger!$E:$E,AGGREGATE(15,6,ROW(Ledger!$B$3:$B$1002)/(Ledger!$B$3:$B$1002=$B$2),2))) | E7: =IF($A7="","",INDEX(Ledger!$F:$F,AGGREGATE(15,6,ROW(Ledger!$B$3:$B$1002)/(Ledger!$B$3:$B$1002=$B$2),2))) | F7: =IF($A7="","",INDEX(Ledger!$H:$H,AGGREGATE(15,6,ROW(Ledger!$B$3:$B$1002)/(Ledger!$B$3:$B$1002=$B$2),2))) | G7: =IF($A7="","",INDEX(Ledger!$I:$I,AGGREGATE(15,6,ROW(Ledger!$B$3:$B$1002)/(Ledger!$B$3:$B$1002=$B$2),2))) | H7: =IF($A7="","",INDEX(Ledger!$K:$K,AGGREGATE(15,6,ROW(Ledger!$B$3:$B$1002)/(Ledger!$B$3:$B$1002=$B$2),2)))
A8: =IFERROR(INDEX(Ledger!$A:$A,AGGREGATE(15,6,ROW(Ledger!$B$3:$B$1002)/(Ledger!$B$3:$B$1002=$B$2),3)),"") | B8: =IF($A8="","",INDEX(Ledger!$C:$C,AGGREGATE(15,6,ROW(Ledger!$B$3:$B$1002)/(Ledger!$B$3:$B$1002=$B$2),3))) | C8: =IF($A8="","",INDEX(Ledger!$D:$D,AGGREGATE(15,6,ROW(Ledger!$B$3:$B$1002)/(Ledger!$B$3:$B$1002=$B$2),3))) | D8: =IF($A8="","",INDEX(Ledger!$E:$E,AGGREGATE(15,6,ROW(Ledger!$B$3:$B$1002)/(Ledger!$B$3:$B$1002=$B$2),3))) | E8: =IF($A8="","",INDEX(Ledger!$F:$F,AGGREGATE(15,6,ROW(Ledger!$B$3:$B$1002)/(Ledger!$B$3:$B$1002=$B$2),3))) | F8: =IF($A8="","",INDEX(Ledger!$H:$H,AGGREGATE(15,6,ROW(Ledger!$B$3:$B$1002)/(Ledger!$B$3:$B$1002=$B$2),3))) | G8: =IF($A8="","",INDEX(Ledger!$I:$I,AGGREGATE(15,6,ROW(Ledger!$B$3:$B$1002)/(Ledger!$B$3:$B$1002=$B$2),3))) | H8: =IF($A8="","",INDEX(Ledger!$K:$K,AGGREGATE(15,6,ROW(Ledger!$B$3:$B$1002)/(Ledger!$B$3:$B$1002=$B$2),3)))
A9: =IFERROR(INDEX(Ledger!$A:$A,AGGREGATE(15,6,ROW(Ledger!$B$3:$B$1002)/(Ledger!$B$3:$B$1002=$B$2),4)),"") | B9: =IF($A9="","",INDEX(Ledger!$C:$C,AGGREGATE(15,6,ROW(Ledger!$B$3:$B$1002)/(Ledger!$B$3:$B$1002=$B$2),4))) | C9: =IF($A9="","",INDEX(Ledger!$D:$D,AGGREGATE(15,6,ROW(Ledger!$B$3:$B$1002)/(Ledger!$B$3:$B$1002=$B$2),4))) | D9: =IF($A9="","",INDEX(Ledger!$E:$E,AGGREGATE(15,6,ROW(Ledger!$B$3:$B$1002)/(Ledger!$B$3:$B$1002=$B$2),4))) | E9: =IF($A9="","",INDEX(Ledger!$F:$F,AGGREGATE(15,6,ROW(Ledger!$B$3:$B$1002)/(Ledger!$B$3:$B$1002=$B$2),4))) | F9: =IF($A9="","",INDEX(Ledger!$H:$H,AGGREGATE(15,6,ROW(Ledger!$B$3:$B$1002)/(Ledger!$B$3:$B$1002=$B$2),4))) | G9: =IF($A9="","",INDEX(Ledger!$I:$I,AGGREGATE(15,6,ROW(Ledger!$B$3:$B$1002)/(Ledger!$B$3:$B$1002=$B$2),4))) | H9: =IF($A9="","",INDEX(Ledger!$K:$K,AGGREGATE(15,6,ROW(Ledger!$B$3:$B$1002)/(Ledger!$B$3:$B$1002=$B$2),4)))
A10: =IFERROR(INDEX(Ledger!$A:$A,AGGREGATE(15,6,ROW(Ledger!$B$3:$B$1002)/(Ledger!$B$3:$B$1002=$B$2),5)),"") | B10: =IF($A10="","",INDEX(Ledger!$C:$C,AGGREGATE(15,6,ROW(Ledger!$B$3:$B$1002)/(Ledger!$B$3:$B$1002=$B$2),5))) | C10: =IF($A10="","",INDEX(Ledger!$D:$D,AGGREGATE(15,6,ROW(Ledger!$B$3:$B$1002)/(Ledger!$B$3:$B$1002=$B$2),5))) | D10: =IF($A10="","",INDEX(Ledger!$E:$E,AGGREGATE(15,6,ROW(Ledger!$B$3:$B$1002)/(Ledger!$B$3:$B$1002=$B$2),5))) | E10: =IF($A10="","",INDEX(Ledger!$F:$F,AGGREGATE(15,6,ROW(Ledger!$B$3:$B$1002)/(Ledger!$B$3:$B$1002=$B$2),5))) | F10: =IF($A10="","",INDEX(Ledger!$H:$H,AGGREGATE(15,6,ROW(Ledger!$B$3:$B$1002)/(Ledger!$B$3:$B$1002=$B$2),5))) | G10: =IF($A10="","",INDEX(Ledger!$I:$I,AGGREGATE(15,6,ROW(Ledger!$B$3:$B$1002)/(Ledger!$B$3:$B$1002=$B$2),5))) | H10: =IF($A10="","",INDEX(Ledger!$K:$K,AGGREGATE(15,6,ROW(Ledger!$B$3:$B$1002)/(Ledger!$B$3:$B$1002=$B$2),5)))
A11: =IFERROR(INDEX(Ledger!$A:$A,AGGREGATE(15,6,ROW(Ledger!$B$3:$B$1002)/(Ledger!$B$3:$B$1002=$B$2),6)),"") | B11: =IF($A11="","",INDEX(Ledger!$C:$C,AGGREGATE(15,6,ROW(Ledger!$B$3:$B$1002)/(Ledger!$B$3:$B$1002=$B$2),6))) | C11: =IF($A11="","",INDEX(Ledger!$D:$D,AGGREGATE(15,6,ROW(Ledger!$B$3:$B$1002)/(Ledger!$B$3:$B$1002=$B$2),6))) | D11: =IF($A11="","",INDEX(Ledger!$E:$E,AGGREGATE(15,6,ROW(Ledger!$B$3:$B$1002)/(Ledger!$B$3:$B$1002=$B$2),6))) | E11: =IF($A11="","",INDEX(Ledger!$F:$F,AGGREGATE(15,6,ROW(Ledger!$B$3:$B$1002)/(Ledger!$B$3:$B$1002=$B$2),6))) | F11: =IF($A11="","",INDEX(Ledger!$H:$H,AGGREGATE(15,6,ROW(Ledger!$B$3:$B$1002)/(Ledger!$B$3:$B$1002=$B$2),6))) | G11: =IF($A11="","",INDEX(Ledger!$I:$I,AGGREGATE(15,6,ROW(Ledger!$B$3:$B$1002)/(Ledger!$B$3:$B$1002=$B$2),6))) | H11: =IF($A11="","",INDEX(Ledger!$K:$K,AGGREGATE(15,6,ROW(Ledger!$B$3:$B$1002)/(Ledger!$B$3:$B$1002=$B$2),6)))
A12: =IFERROR(INDEX(Ledger!$A:$A,AGGREGATE(15,6,ROW(Ledger!$B$3:$B$1002)/(Ledger!$B$3:$B$1002=$B$2),7)),"") | B12: =IF($A12="","",INDEX(Ledger!$C:$C,AGGREGATE(15,6,ROW(Ledger!$B$3:$B$1002)/(Ledger!$B$3:$B$1002=$B$2),7))) | C12: =IF($A12="","",INDEX(Ledger!$D:$D,AGGREGATE(15,6,ROW(Ledger!$B$3:$B$1002)/(Ledger!$B$3:$B$1002=$B$2),7))) | D12: =IF($A12="","",INDEX(Ledger!$E:$E,AGGREGATE(15,6,ROW(Ledger!$B$3:$B$1002)/(Ledger!$B$3:$B$1002=$B$2),7))) | E12: =IF($A12="","",INDEX(Ledger!$F:$F,AGGREGATE(15,6,ROW(Ledger!$B$3:$B$1002)/(Ledger!$B$3:$B$1002=$B$2),7))) | F12: =IF($A12="","",INDEX(Ledger!$H:$H,AGGREGATE(15,6,ROW(Ledger!$B$3:$B$1002)/(Ledger!$B$3:$B$1002=$B$2),7))) | G12: =IF($A12="","",INDEX(Ledger!$I:$I,AGGREGATE(15,6,ROW(Ledger!$B$3:$B$1002)/(Ledger!$B$3:$B$1002=$B$2),7))) | H12: =IF($A12="","",INDEX(Ledger!$K:$K,AGGREGATE(15,6,ROW(Ledger!$B$3:$B$1002)/(Ledger!$B$3:$B$1002=$B$2),7)))
A13: =IFERROR(INDEX(Ledger!$A:$A,AGGREGATE(15,6,ROW(Ledger!$B$3:$B$1002)/(Ledger!$B$3:$B$1002=$B$2),8)),"") | B13: =IF($A13="","",INDEX(Ledger!$C:$C,AGGREGATE(15,6,ROW(Ledger!$B$3:$B$1002)/(Ledger!$B$3:$B$1002=$B$2),8))) | C13: =IF($A13="","",INDEX(Ledger!$D:$D,AGGREGATE(15,6,ROW(Ledger!$B$3:$B$1002)/(Ledger!$B$3:$B$1002=$B$2),8))) | D13: =IF($A13="","",INDEX(Ledger!$E:$E,AGGREGATE(15,6,ROW(Ledger!$B$3:$B$1002)/(Ledger!$B$3:$B$1002=$B$2),8))) | E13: =IF($A13="","",INDEX(Ledger!$F:$F,AGGREGATE(15,6,ROW(Ledger!$B$3:$B$1002)/(Ledger!$B$3:$B$1002=$B$2),8))) | F13: =IF($A13="","",INDEX(Ledger!$H:$H,AGGREGATE(15,6,ROW(Ledger!$B$3:$B$1002)/(Ledger!$B$3:$B$1002=$B$2),8))) | G13: =IF($A13="","",INDEX(Ledger!$I:$I,AGGREGATE(15,6,ROW(Ledger!$B$3:$B$1002)/(Ledger!$B$3:$B$1002=$B$2),8))) | H13: =IF($A13="","",INDEX(Ledger!$K:$K,AGGREGATE(15,6,ROW(Ledger!$B$3:$B$1002)/(Ledger!$B$3:$B$1002=$B$2),8)))
A14: =IFERROR(INDEX(Ledger!$A:$A,AGGREGATE(15,6,ROW(Ledger!$B$3:$B$1002)/(Ledger!$B$3:$B$1002=$B$2),9)),"") | B14: =IF($A14="","",INDEX(Ledger!$C:$C,AGGREGATE(15,6,ROW(Ledger!$B$3:$B$1002)/(Ledger!$B$3:$B$1002=$B$2),9))) | C14: =IF($A14="","",INDEX(Ledger!$D:$D,AGGREGATE(15,6,ROW(Ledger!$B$3:$B$1002)/(Ledger!$B$3:$B$1002=$B$2),9))) | D14: =IF($A14="","",INDEX(Ledger!$E:$E,AGGREGATE(15,6,ROW(Ledger!$B$3:$B$1002)/(Ledger!$B$3:$B$1002=$B$2),9))) | E14: =IF($A14="","",INDEX(Ledger!$F:$F,AGGREGATE(15,6,ROW(Ledger!$B$3:$B$1002)/(Ledger!$B$3:$B$1002=$B$2),9))) | F14: =IF($A14="","",INDEX(Ledger!$H:$H,AGGREGATE(15,6,ROW(Ledger!$B$3:$B$1002)/(Ledger!$B$3:$B$1002=$B$2),9))) | G14: =IF($A14="","",INDEX(Ledger!$I:$I,AGGREGATE(15,6,ROW(Ledger!$B$3:$B$1002)/(Ledger!$B$3:$B$1002=$B$2),9))) | H14: =IF($A14="","",INDEX(Ledger!$K:$K,AGGREGATE(15,6,ROW(Ledger!$B$3:$B$1002)/(Ledger!$B$3:$B$1002=$B$2),9)))
A15: =IFERROR(INDEX(Ledger!$A:$A,AGGREGATE(15,6,ROW(Ledger!$B$3:$B$1002)/(Ledger!$B$3:$B$1002=$B$2),10)),"") | B15: =IF($A15="","",INDEX(Ledger!$C:$C,AGGREGATE(15,6,ROW(Ledger!$B$3:$B$1002)/(Ledger!$B$3:$B$1002=$B$2),10))) | C15: =IF($A15="","",INDEX(Ledger!$D:$D,AGGREGATE(15,6,ROW(Ledger!$B$3:$B$1002)/(Ledger!$B$3:$B$1002=$B$2),10))) | D15: =IF($A15="","",INDEX(Ledger!$E:$E,AGGREGATE(15,6,ROW(Ledger!$B$3:$B$1002)/(Ledger!$B$3:$B$1002=$B$2),10))) | E15: =IF($A15="","",INDEX(Ledger!$F:$F,AGGREGATE(15,6,ROW(Ledger!$B$3:$B$1002)/(Ledger!$B$3:$B$1002=$B$2),10))) | F15: =IF($A15="","",INDEX(Ledger!$H:$H,AGGREGATE(15,6,ROW(Ledger!$B$3:$B$1002)/(Ledger!$B$3:$B$1002=$B$2),10))) | G15: =IF($A15="","",INDEX(Ledger!$I:$I,AGGREGATE(15,6,ROW(Ledger!$B$3:$B$1002)/(Ledger!$B$3:$B$1002=$B$2),10))) | H15: =IF($A15="","",INDEX(Ledger!$K:$K,AGGREGATE(15,6,ROW(Ledger!$B$3:$B$1002)/(Ledger!$B$3:$B$1002=$B$2),10)))
A16: =IFERROR(INDEX(Ledger!$A:$A,AGGREGATE(15,6,ROW(Ledger!$B$3:$B$1002)/(Ledger!$B$3:$B$1002=$B$2),11)),"") | B16: =IF($A16="","",INDEX(Ledger!$C:$C,AGGREGATE(15,6,ROW(Ledger!$B$3:$B$1002)/(Ledger!$B$3:$B$1002=$B$2),11))) | C16: =IF($A16="","",INDEX(Ledger!$D:$D,AGGREGATE(15,6,ROW(Ledger!$B$3:$B$1002)/(Ledger!$B$3:$B$1002=$B$2),11))) | D16: =IF($A16="","",INDEX(Ledger!$E:$E,AGGREGATE(15,6,ROW(Ledger!$B$3:$B$1002)/(Ledger!$B$3:$B$1002=$B$2),11))) | E16: =IF($A16="","",INDEX(Ledger!$F:$F,AGGREGATE(15,6,ROW(Ledger!$B$3:$B$1002)/(Ledger!$B$3:$B$1002=$B$2),11))) | F16: =IF($A16="","",INDEX(Ledger!$H:$H,AGGREGATE(15,6,ROW(Ledger!$B$3:$B$1002)/(Ledger!$B$3:$B$1002=$B$2),11))) | G16: =IF($A16="","",INDEX(Ledger!$I:$I,AGGREGATE(15,6,ROW(Ledger!$B$3:$B$1002)/(Ledger!$B$3:$B$1002=$B$2),11))) | H16: =IF($A16="","",INDEX(Ledger!$K:$K,AGGREGATE(15,6,ROW(Ledger!$B$3:$B$1002)/(Ledger!$B$3:$B$1002=$B$2),11)))
A17: =IFERROR(INDEX(Ledger!$A:$A,AGGREGATE(15,6,ROW(Ledger!$B$3:$B$1002)/(Ledger!$B$3:$B$1002=$B$2),12)),"") | B17: =IF($A17="","",INDEX(Ledger!$C:$C,AGGREGATE(15,6,ROW(Ledger!$B$3:$B$1002)/(Ledger!$B$3:$B$1002=$B$2),12))) | C17: =IF($A17="","",INDEX(Ledger!$D:$D,AGGREGATE(15,6,ROW(Ledger!$B$3:$B$1002)/(Ledger!$B$3:$B$1002=$B$2),12))) | D17: =IF($A17="","",INDEX(Ledger!$E:$E,AGGREGATE(15,6,ROW(Ledger!$B$3:$B$1002)/(Ledger!$B$3:$B$1002=$B$2),12))) | E17: =IF($A17="","",INDEX(Ledger!$F:$F,AGGREGATE(15,6,ROW(Ledger!$B$3:$B$1002)/(Ledger!$B$3:$B$1002=$B$2),12))) | F17: =IF($A17="","",INDEX(Ledger!$H:$H,AGGREGATE(15,6,ROW(Ledger!$B$3:$B$1002)/(Ledger!$B$3:$B$1002=$B$2),12))) | G17: =IF($A17="","",INDEX(Ledger!$I:$I,AGGREGATE(15,6,ROW(Ledger!$B$3:$B$1002)/(Ledger!$B$3:$B$1002=$B$2),12))) | H17: =IF($A17="","",INDEX(Ledger!$K:$K,AGGREGATE(15,6,ROW(Ledger!$B$3:$B$1002)/(Ledger!$B$3:$B$1002=$B$2),12)))
A18: =IFERROR(INDEX(Ledger!$A:$A,AGGREGATE(15,6,ROW(Ledger!$B$3:$B$1002)/(Ledger!$B$3:$B$1002=$B$2),13)),"") | B18: =IF($A18="","",INDEX(Ledger!$C:$C,AGGREGATE(15,6,ROW(Ledger!$B$3:$B$1002)/(Ledger!$B$3:$B$1002=$B$2),13))) | C18: =IF($A18="","",INDEX(Ledger!$D:$D,AGGREGATE(15,6,ROW(Ledger!$B$3:$B$1002)/(Ledger!$B$3:$B$1002=$B$2),13))) | D18: =IF($A18="","",INDEX(Ledger!$E:$E,AGGREGATE(15,6,ROW(Ledger!$B$3:$B$1002)/(Ledger!$B$3:$B$1002=$B$2),13))) | E18: =IF($A18="","",INDEX(Ledger!$F:$F,AGGREGATE(15,6,ROW(Ledger!$B$3:$B$1002)/(Ledger!$B$3:$B$1002=$B$2),13))) | F18: =IF($A18="","",INDEX(Ledger!$H:$H,AGGREGATE(15,6,ROW(Ledger!$B$3:$B$1002)/(Ledger!$B$3:$B$1002=$B$2),13))) | G18: =IF($A18="","",INDEX(Ledger!$I:$I,AGGREGATE(15,6,ROW(Ledger!$B$3:$B$1002)/(Ledger!$B$3:$B$1002=$B$2),13))) | H18: =IF($A18="","",INDEX(Ledger!$K:$K,AGGREGATE(15,6,ROW(Ledger!$B$3:$B$1002)/(Ledger!$B$3:$B$1002=$B$2),13)))
A19: =IFERROR(INDEX(Ledger!$A:$A,AGGREGATE(15,6,ROW(Ledger!$B$3:$B$1002)/(Ledger!$B$3:$B$1002=$B$2),14)),"") | B19: =IF($A19="","",INDEX(Ledger!$C:$C,AGGREGATE(15,6,ROW(Ledger!$B$3:$B$1002)/(Ledger!$B$3:$B$1002=$B$2),14))) | C19: =IF($A19="","",INDEX(Ledger!$D:$D,AGGREGATE(15,6,ROW(Ledger!$B$3:$B$1002)/(Ledger!$B$3:$B$1002=$B$2),14))) | D19: =IF($A19="","",INDEX(Ledger!$E:$E,AGGREGATE(15,6,ROW(Ledger!$B$3:$B$1002)/(Ledger!$B$3:$B$1002=$B$2),14))) | E19: =IF($A19="","",INDEX(Ledger!$F:$F,AGGREGATE(15,6,ROW(Ledger!$B$3:$B$1002)/(Ledger!$B$3:$B$1002=$B$2),14))) | F19: =IF($A19="","",INDEX(Ledger!$H:$H,AGGREGATE(15,6,ROW(Ledger!$B$3:$B$1002)/(Ledger!$B$3:$B$1002=$B$2),14))) | G19: =IF($A19="","",INDEX(Ledger!$I:$I,AGGREGATE(15,6,ROW(Ledger!$B$3:$B$1002)/(Ledger!$B$3:$B$1002=$B$2),14))) | H19: =IF($A19="","",INDEX(Ledger!$K:$K,AGGREGATE(15,6,ROW(Ledger!$B$3:$B$1002)/(Ledger!$B$3:$B$1002=$B$2),14)))
A20: =IFERROR(INDEX(Ledger!$A:$A,AGGREGATE(15,6,ROW(Ledger!$B$3:$B$1002)/(Ledger!$B$3:$B$1002=$B$2),15)),"") | B20: =IF($A20="","",INDEX(Ledger!$C:$C,AGGREGATE(15,6,ROW(Ledger!$B$3:$B$1002)/(Ledger!$B$3:$B$1002=$B$2),15))) | C20: =IF($A20="","",INDEX(Ledger!$D:$D,AGGREGATE(15,6,ROW(Ledger!$B$3:$B$1002)/(Ledger!$B$3:$B$1002=$B$2),15))) | D20: =IF($A20="","",INDEX(Ledger!$E:$E,AGGREGATE(15,6,ROW(Ledger!$B$3:$B$1002)/(Ledger!$B$3:$B$1002=$B$2),15))) | E20: =IF($A20="","",INDEX(Ledger!$F:$F,AGGREGATE(15,6,ROW(Ledger!$B$3:$B$1002)/(Ledger!$B$3:$B$1002=$B$2),15))) | F20: =IF($A20="","",INDEX(Ledger!$H:$H,AGGREGATE(15,6,ROW(Ledger!$B$3:$B$1002)/(Ledger!$B$3:$B$1002=$B$2),15))) | G20: =IF($A20="","",INDEX(Ledger!$I:$I,AGGREGATE(15,6,ROW(Ledger!$B$3:$B$1002)/(Ledger!$B$3:$B$1002=$B$2),15))) | H20: =IF($A20="","",INDEX(Ledger!$K:$K,AGGREGATE(15,6,ROW(Ledger!$B$3:$B$1002)/(Ledger!$B$3:$B$1002=$B$2),15)))
A21: =IFERROR(INDEX(Ledger!$A:$A,AGGREGATE(15,6,ROW(Ledger!$B$3:$B$1002)/(Ledger!$B$3:$B$1002=$B$2),16)),"") | B21: =IF($A21="","",INDEX(Ledger!$C:$C,AGGREGATE(15,6,ROW(Ledger!$B$3:$B$1002)/(Ledger!$B$3:$B$1002=$B$2),16))) | C21: =IF($A21="","",INDEX(Ledger!$D:$D,AGGREGATE(15,6,ROW(Ledger!$B$3:$B$1002)/(Ledger!$B$3:$B$1002=$B$2),16))) | D21: =IF($A21="","",INDEX(Ledger!$E:$E,AGGREGATE(15,6,ROW(Ledger!$B$3:$B$1002)/(Ledger!$B$3:$B$1002=$B$2),16))) | E21: =IF($A21="","",INDEX(Ledger!$F:$F,AGGREGATE(15,6,ROW(Ledger!$B$3:$B$1002)/(Ledger!$B$3:$B$1002=$B$2),16))) | F21: =IF($A21="","",INDEX(Ledger!$H:$H,AGGREGATE(15,6,ROW(Ledger!$B$3:$B$1002)/(Ledger!$B$3:$B$1002=$B$2),16))) | G21: =IF($A21="","",INDEX(Ledger!$I:$I,AGGREGATE(15,6,ROW(Ledger!$B$3:$B$1002)/(Ledger!$B$3:$B$1002=$B$2),16))) | H21: =IF($A21="","",INDEX(Ledger!$K:$K,AGGREGATE(15,6,ROW(Ledger!$B$3:$B$1002)/(Ledger!$B$3:$B$1002=$B$2),16)))
A22: =IFERROR(INDEX(Ledger!$A:$A,AGGREGATE(15,6,ROW(Ledger!$B$3:$B$1002)/(Ledger!$B$3:$B$1002=$B$2),17)),"") | B22: =IF($A22="","",INDEX(Ledger!$C:$C,AGGREGATE(15,6,ROW(Ledger!$B$3:$B$1002)/(Ledger!$B$3:$B$1002=$B$2),17))) | C22: =IF($A22="","",INDEX(Ledger!$D:$D,AGGREGATE(15,6,ROW(Ledger!$B$3:$B$1002)/(Ledger!$B$3:$B$1002=$B$2),17))) | D22: =IF($A22="","",INDEX(Ledger!$E:$E,AGGREGATE(15,6,ROW(Ledger!$B$3:$B$1002)/(Ledger!$B$3:$B$1002=$B$2),17))) | E22: =IF($A22="","",INDEX(Ledger!$F:$F,AGGREGATE(15,6,ROW(Ledger!$B$3:$B$1002)/(Ledger!$B$3:$B$1002=$B$2),17))) | F22: =IF($A22="","",INDEX(Ledger!$H:$H,AGGREGATE(15,6,ROW(Ledger!$B$3:$B$1002)/(Ledger!$B$3:$B$1002=$B$2),17))) | G22: =IF($A22="","",INDEX(Ledger!$I:$I,AGGREGATE(15,6,ROW(Ledger!$B$3:$B$1002)/(Ledger!$B$3:$B$1002=$B$2),17))) | H22: =IF($A22="","",INDEX(Ledger!$K:$K,AGGREGATE(15,6,ROW(Ledger!$B$3:$B$1002)/(Ledger!$B$3:$B$1002=$B$2),17)))
A23: =IFERROR(INDEX(Ledger!$A:$A,AGGREGATE(15,6,ROW(Ledger!$B$3:$B$1002)/(Ledger!$B$3:$B$1002=$B$2),18)),"") | B23: =IF($A23="","",INDEX(Ledger!$C:$C,AGGREGATE(15,6,ROW(Ledger!$B$3:$B$1002)/(Ledger!$B$3:$B$1002=$B$2),18))) | C23: =IF($A23="","",INDEX(Ledger!$D:$D,AGGREGATE(15,6,ROW(Ledger!$B$3:$B$1002)/(Ledger!$B$3:$B$1002=$B$2),18))) | D23: =IF($A23="","",INDEX(Ledger!$E:$E,AGGREGATE(15,6,ROW(Ledger!$B$3:$B$1002)/(Ledger!$B$3:$B$1002=$B$2),18))) | E23: =IF($A23="","",INDEX(Ledger!$F:$F,AGGREGATE(15,6,ROW(Ledger!$B$3:$B$1002)/(Ledger!$B$3:$B$1002=$B$2),18))) | F23: =IF($A23="","",INDEX(Ledger!$H:$H,AGGREGATE(15,6,ROW(Ledger!$B$3:$B$1002)/(Ledger!$B$3:$B$1002=$B$2),18))) | G23: =IF($A23="","",INDEX(Ledger!$I:$I,AGGREGATE(15,6,ROW(Ledger!$B$3:$B$1002)/(Ledger!$B$3:$B$1002=$B$2),18))) | H23: =IF($A23="","",INDEX(Ledger!$K:$K,AGGREGATE(15,6,ROW(Ledger!$B$3:$B$1002)/(Ledger!$B$3:$B$1002=$B$2),18)))
